Workbook
Name PHOTO1: INDEX(PHOTO!$F$4:PHOTO!$F$103,MATCH(PHOTO!$H$2,PHOTO!$A$4:PHOTO!$A$103,0))
Name PHOTO2: INDEX(PHOTO!$F$4:PHOTO!$F$103,MATCH('ALL-F1'!$I$11,PHOTO!$A$4:PHOTO!$A$103,0))
Name PHOTO2: INDEX(PHOTO!$F$4:PHOTO!$F$103,MATCH('BAR-F1'!$I$11,PHOTO!$A$4:PHOTO!$A$103,0))
Name PHOTO2: INDEX(PHOTO!$F$4:PHOTO!$F$103,MATCH('F1'!$I$11,PHOTO!$A$4:PHOTO!$A$103,0))
Name PHOTO2: INDEX(PHOTO!$F$4:PHOTO!$F$103,MATCH(#REF!,PHOTO!$A$4:PHOTO!$A$103,0))
Name PHOTO2: INDEX(PHOTO!$F$4:PHOTO!$F$103,MATCH(#REF!,PHOTO!$A$4:PHOTO!$A$103,0))
Name PHOTO3: INDEX(PHOTO!$F$4:PHOTO!$F$103,MATCH('AB1'!$N$12,PHOTO!$A$4:PHOTO!$A$103,0))
Name PHOTO4: INDEX(PHOTO!$F$4:PHOTO!$F$103,MATCH(SUCCESS!$P$13,PHOTO!$A$4:PHOTO!$A$103,0))

Sheet ENTRY
B1: COMMON DETAILS OF SCHOOL : | F1: INPUT SHEETS (ENTRY) | M1: OUTPUT SHEETS (PRINT)
A2: 1 | B2: SHORT NAME OF CORPORATION | C2: : | D2: MCD
A3: 2 | B3: CORPORATION NAME | C3: : | D3: MUNICIPAL CORPORATION OF DELHI | E3: 1 | F3: DATEWISE | L3: 1 | M3: STUDENT FLN ASSESSMENT SHEET
A4: 3 | B4: NAME OF DEPARTMENT | C4: : | D4: EDUCATION DEPARTMENT
A5: 4 | B5: ZONE | C5: : | D5: ROHINI ZONE | E5: 2 | F5: STUDENT | L5: 2 | M5: STUDENT FLN RECORD - ANNEXURE-F1
A6: 5 | B6: NAME OF THE SCHOOL | C6: : | D6: MCP NITHARI NO 1 BOYS
A7: 6 | B7: School U-DISE ID | C7: : | E7: 3 | F7: FLN | L7: 3 | M7: CLASS WISE FLN RECORD - ANNEXURE-F2
A8: 7 | B8: School U-DISE CODE | C8: :
A9: 8 | B9: School Number | C9: : | D9: 20 | E9: 4 | F9: PHOTO | L9: 4 | M9: BAR GRAPH - ANNEXURE-F1
A10: 9 | B10: Ward No. | C10: : | D10: 40
A11: 10 | B11: Session | C11: : | D11: 2026-27 | E11: 5 | F11: PASHEET | L11: 5 | M11: P.A. SUMMARY
A12: 11 | B12: Name of Principal / HOS | C12: : | D12: SHAMBHU DAYAL MEENA
A13: 12 | B13: Name of Mentor | C13: : | D13: DEVENDER SINGH | E13: 6 | F13: MARKS | L13: 6 | M13: STUDENT MARKS CARD - ANNEXURE-AB1
A14: 13 | B14: Name of S.I. of School | C14: :
A15: 14 | B15: Total Students in School | C15: : | E15: 7 | F15: ATTENDANCE | L15: 7 | M15: CASE STUDY
A16: 15 | B16: Total Students (3rd to 5th) in MB | C16: :
A17: 16 | B17: Total Long Absentee (3rd to 5th) in MB | C17: : | L17: 8 | M17: SUCCESS STORY
A18: 17 | B18: Total Available Students in MB | C18: :
A19: 18 | B19: Name of Class Teacher | C19: : | D19: INDRAJEET | L19: 9 | M19: PTM FEEDBACK
A20: 19 | B20: Class | C20: : | D20: III
A21: 20 | B21: Section | C21: : | D21: A | L21: 10 | M21: RESULT REGISTER - ANNEXURE-R2.1 - 1 to 4
A22: 21 | B22: Total Boys in Class | C22: : | D22: 39
A23: 22 | B23: Total Girls in Class | C23: : | D23: 0 | L23: 11 | M23: CLASS WISE SUMMARY-ANNEXURE-R2.2 - 1 to 4
A24: 23 | B24: Total Students in the Class | C24: : | D24: 39
A25: 24 | B25: Total Working Days (Apr to Sep) | C25: : | L25: 12 | M25: SCHOOL WISE SUM - ANNEXURE-R2.3 - 1 to 4
A26: 25 | B26: Total Working Days (April to March) | C26: :
A27: 26 | B27: Date of Result Declaration | C27: : | D27: 46102 | L27: 13 | M27: MARKS SHEET - ANNEXURE-R2.4 - 1 to 4
A28: 27 | B28: State | C28: : | D28: NEW DELHI
A29: 28 | B29: BMID of Class Teacher | C29: : | D29: 95032137 | L29: 14 | M29: RESULT REGISTER - ANNEXURE-R3.1 - 5TH
A30: 29 | B30: Contact Number of Teacher | C30: : | D30: 9958606952
A31: 30 | B31: Name of Academic Co-ordinator | C31: : | L31: 15 | M31: CLASS WISE SUMMARY - ANNEXURE-R3.2 - 5TH
A32: 31 | B32: Contact No. of Academic Co-ordinator | C32: :
A33: 32 | B33: Contact No. of HOS | C33: : | L33: 16 | M33: SCHOOL WISE SUM - ANNEXURE-R3.3 - 5TH
A34: 33
A35: 34 | L35: 17 | M35: MARKS SHEET - ANNEXURE-R3.4 - 5TH
A36: 35
A37: 36 | L37: 18 | M37: ALL STUDENTS FLN GRAPH - F1
A38: 37
A39: 38 | L39: 19 | M39: SCHOOL WISE FLN 1 & 2 - ANNEXURE-F3.1
A40: 39
...

Sheet DATEWISE
A1: DATES OF FLN ASSESSMENT | C1: Total Students in the Class | D1: Total Long Absentee | E1: Total Students Assessed | F1: Total Students in the SCHOOL (1st to 2nd) | G1: Total Long Absentee (1st to 2nd) | H1: Total Students Assessed (1st to 2nd) | I1: CODE | J1: HINDI | O1: Total Students Assessed (1st to 2nd) | P1: CODE | Q1: MATHS | V1: Total Students Assessed (1st to 2nd) | W1: CODE | X1: ENGLISH | AC1: Total Students Assessed (1st to 2nd) | AD1: Total Students in the SCHOOL (3rd to 5th) | AE1: Total Long Absentee (3rd to 5th) | AF1: Total Students Assessed (3rd to 5th) | AG1: CODE | AH1: HINDI | AM1: Total Students Assessed (3rd to 5th) | AN1: CODE | AO1: MATHS | AT1: Total Students Assessed (3rd to 5th) | AU1: CODE | AV1: ENGLISH | BA1: Total Students Assessed (3rd to 5th) | BB1: Total Students in the SCHOOL (1st to 5th) | BC1: Total Long Absentee (1st to 5th) | BD1: Total Students Assessed (1st to 5th) | BE1: CODE | BF1: HINDI | BK1: Total Students Assessed (1st to 5th) | BL1: CODE | BM1: MATHS | BR1: Total Students Assessed (1st to 5th) | BS1: CODE | BT1: ENGLISH | BY1: Total Students Assessed (1st to 5th) | BZ1: HINDI | CF1: Total Students Assessed | CG1: MATHS | CM1: Total Students Assessed | CN1: ENGLISH | CT1: Total Students Assessed
J2: L1 | K2: L2 | L2: L3 | M2: L4 | N2: L5 | O2: HINDI | Q2: L1 | R2: L2 | S2: L3 | T2: L4 | U2: L5 | V2: MATHS | X2: L1 | Y2: L2 | Z2: L3 | AA2: L4 | AB2: L5 | AC2: ENGLISH | AH2: L1 | AI2: L2 | AJ2: L3 | AK2: L4 | AL2: L5 | AM2: HINDI | AO2: L1 | AP2: L2 | AQ2: L3 | AR2: L4 | AS2: L5 | AT2: MATHS | AV2: L1 | AW2: L2 | AX2: L3 | AY2: L4 | AZ2: L5 | BA2: ENGLISH | BF2: L1 | BG2: L2 | BH2: L3 | BI2: L4 | BJ2: L5 | BK2: HINDI | BM2: L1 | BN2: L2 | BO2: L3 | BP2: L4 | BQ2: L5 | BR2: MATHS | BT2: L1 | BU2: L2 | BV2: L3 | BW2: L4 | BX2: L5 | BY2: ENGLISH | BZ2: L1 | CA2: L2 | CB2: L3 | CC2: L4 | CD2: L5 | CE2: Ab | CF2: TOTAL | CG2: L1 | CH2: L2 | CI2: L3 | CJ2: L4 | CK2: L5 | CL2: Ab | CM2: TOTAL | CN2: L1 | CO2: L2 | CP2: L3 | CQ2: L4 | CR2: L5 | CS2: Ab | CT2: TOTAL
A3: 1 | B3: 30.04.2026 | C3: 39 | D3: 3 | E3: =IF(C3>0,MIN(C3-D3),"") -> 36 | G3: 0 | H3: =IF(F3>0,MIN(F3-G3),"") | I3: =B3&$J$1 -> 30.04.2026HINDI | J3: 8 | K3: 24 | L3: 7 | M3: 0 | N3: 0 | O3: =IF(F3>0,SUM(J3,K3,L3,M3,N3),"") | P3: =B3&$Q$1 -> 30.04.2026MATHS | Q3: 8 | R3: 24 | S3: 7 | T3: 0 | U3: 0 | V3: =IF(F3>0,SUM(Q3,R3,S3,T3,U3),"") | W3: =B3&$X$1 -> 30.04.2026ENGLISH | X3: 8 | Y3: 24 | Z3: 7 | AA3: 0 | AB3: 0 | AC3: =IF(F3>0,SUM(X3,Y3,Z3,AA3,AB3),"") | AD3: 687 | AE3: 3 | AF3: =IF(AD3>0,MIN(AD3-AE3),"") -> 684 | AG3: =B3&$AH$1 -> 30.04.2026HINDI | AH3: 12 | AI3: 106 | AJ3: 388 | AK3: 155 | AL3: 23 | AM3: =IF(AD3>0,SUM(AH3,AI3,AJ3,AK3,AL3),"") -> 684 | AN3: =B3&$AO$1 -> 30.04.2026MATHS | AO3: 12 | AP3: 96 | AQ3: 384 | AR3: 169 | AS3: 23 | AT3: =IF(AD3>0,SUM(AO3,AP3,AQ3,AR3,AS3),"") -> 684 | AU3: =B3&$AV$1 -> 30.04.2026ENGLISH | AV3: 12 | AW3: 138 | AX3: 374 | AY3: 137 | AZ3: 23 | BA3: =IF(AD3>0,SUM(AV3,AW3,AX3,AY3,AZ3),"") -> 684 | BB3: =SUM(F3,AD3) -> 687 | BC3: =SUM(G3,AE3) -> 3 | BD3: =IF(BB3>0,MIN(BB3-BC3),"") -> 684 | BE3: =B3&$BF$1 -> 30.04.2026HINDI | BF3: =SUM(J3,AH3) -> 20 | BG3: =SUM(K3,AI3) -> 130 | BH3: =SUM(L3,AJ3) -> 395 | BI3: =SUM(M3,AK3) -> 155 | BJ3: =SUM(N3,AL3) -> 23 | BK3: =IF(BB3>0,SUM(BF3,BG3,BH3,BI3,BJ3),"") -> 723 | BL3: =B3&$BM$1 -> 30.04.2026MATHS | BM3: =SUM(Q3,AO3) -> 20 | BN3: =SUM(R3,AP3) -> 120 | BO3: =SUM(S3,AQ3) -> 391 | BP3: =SUM(T3,AR3) -> 169 | BQ3: =SUM(U3,AS3) -> 23 | BR3: =IF(BB3>0,SUM(BM3,BN3,BO3,BP3,BQ3),"") -> 723 | BS3: =B3&$BT$1 -> 30.04.2026ENGLISH | BT3: =SUM(X3,AV3) -> 20 | BU3: =SUM(Y3,AW3) -> 162 | BV3: =SUM(Z3,AX3) -> 381 | BW3: =SUM(AA3,AY3) -> 137 | BX3: =SUM(AB3,AZ3) -> 23 | BY3: =IF(BB3>0,SUM(BT3,BU3,BV3,BW3,BX3),"") -> 723 | BZ3: =IF(E3="","",VLOOKUP(B3&$BZ$1,FLNTRANSPOSE!$F$3:$DP$102,105,0)) -> 0 | CA3: =IF(E3="","",VLOOKUP(B3&$BZ$1,FLNTRANSPOSE!$F$3:$DP$102,107,0)) -> 28 | CB3: =IF(E3="","",VLOOKUP(B3&$BZ$1,FLNTRANSPOSE!$F$3:$DP$102,109,0)) -> 5 | CC3: =IF(E3="","",VLOOKUP(B3&$BZ$1,FLNTRANSPOSE!$F$3:$DP$102,111,0)) -> 3 | CD3: =IF(E3="","",VLOOKUP(B3&$BZ$1,FLNTRANSPOSE!$F$3:$DP$102,113,0)) -> 0 | CE3: =IF(E3="","",VLOOKUP(B3&$BZ$1,FLNTRANSPOSE!$F$3:$DP$102,115,0)) -> 3 | CF3: =IF(E3="","",SUM(BZ3,CA3,CB3,CC3,CD3,CE3)) -> 39 | CG3: =IF(E3="","",VLOOKUP(B3&$CG$1,FLNTRANSPOSE!$F$3:$DP$102,105,0)) -> 0 | CH3: =IF(E3="","",VLOOKUP(B3&$CG$1,FLNTRANSPOSE!$F$3:$DP$102,107,0)) -> 0 | CI3: =IF(E3="","",VLOOKUP(B3&$CG$1,FLNTRANSPOSE!$F$3:$DP$102,109,0)) -> 27 | CJ3: =IF(E3="","",VLOOKUP(B3&$CG$1,FLNTRANSPOSE!$F$3:$DP$102,111,0)) -> 9 | CK3: =IF(E3="","",VLOOKUP(B3&$CG$1,FLNTRANSPOSE!$F$3:$DP$102,113,0)) -> 0 | CL3: =IF(E3="","",VLOOKUP(B3&$CG$1,FLNTRANSPOSE!$F$3:$DP$102,115,0)) -> 3 | CM3: =IF(E3="","",SUM(CG3,CH3,CI3,CJ3,CK3,CL3)) -> 39 | CN3: =IF(E3="","",VLOOKUP(B3&$CN$1,FLNTRANSPOSE!$F$3:$DP$102,105,0)) -> 0 | CO3: =IF(E3="","",VLOOKUP(B3&$CN$1,FLNTRANSPOSE!$F$3:$DP$102,107,0)) -> 31 | CP3: =IF(E3="","",VLOOKUP(B3&$CN$1,FLNTRANSPOSE!$F$3:$DP$102,109,0)) -> 5 | CQ3: =IF(E3="","",VLOOKUP(B3&$CN$1,FLNTRANSPOSE!$F$3:$DP$102,111,0)) -> 0 | CR3: =IF(E3="","",VLOOKUP(B3&$CN$1,FLNTRANSPOSE!$F$3:$DP$102,113,0)) -> 0 | CS3: =IF(E3="","",VLOOKUP(B3&$CN$1,FLNTRANSPOSE!$F$3:$DP$102,115,0)) -> 3 | CT3: =IF(E3="","",SUM(CN3,CO3,CP3,CQ3,CR3,CS3)) -> 39
A4: 2 | B4: 08.05.2026 | C4: 39 | D4: 3 | E4: =IF(C4>0,MIN(C4-D4),"") -> 36 | G4: 0 | H4: =IF(F4>0,MIN(F4-G4),"") | I4: =B4&$J$1 -> 08.05.2026HINDI | J4: 0 | K4: 24 | L4: 15 | M4: 0 | N4: 0 | O4: =IF(F4>0,SUM(J4,K4,L4,M4,N4),"") | P4: =B4&$Q$1 -> 08.05.2026MATHS | Q4: 110 | R4: 72 | S4: 18 | T4: 0 | U4: 0 | V4: =IF(F4>0,SUM(Q4,R4,S4,T4,U4),"") | W4: =B4&$X$1 -> 08.05.2026ENGLISH | X4: 110 | Y4: 72 | Z4: 18 | AA4: 0 | AB4: 0 | AC4: =IF(F4>0,SUM(X4,Y4,Z4,AA4,AB4),"") | AD4: 711 | AE4: 0 | AF4: =IF(AD4>0,MIN(AD4-AE4),"") -> 711 | AG4: =B4&$AH$1 -> 08.05.2026HINDI | AH4: 12 | AI4: 137 | AJ4: 388 | AK4: 151 | AL4: 23 | AM4: =IF(AD4>0,SUM(AH4,AI4,AJ4,AK4,AL4),"") -> 711 | AN4: =B4&$AO$1 -> 08.05.2026MATHS | AO4: 12 | AP4: 127 | AQ4: 384 | AR4: 165 | AS4: 23 | AT4: =IF(AD4>0,SUM(AO4,AP4,AQ4,AR4,AS4),"") -> 711 | AU4: =B4&$AV$1 -> 08.05.2026ENGLISH | AV4: 12 | AW4: 169 | AX4: 374 | AY4: 133 | AZ4: 23 | BA4: =IF(AD4>0,SUM(AV4,AW4,AX4,AY4,AZ4),"") -> 711 | BB4: =SUM(F4,AD4) -> 711 | BC4: =SUM(G4,AE4) -> 0 | BD4: =IF(BB4>0,MIN(BB4-BC4),"") -> 711 | BE4: =B4&$BF$1 -> 08.05.2026HINDI | BF4: =SUM(J4,AH4) -> 12 | BG4: =SUM(K4,AI4) -> 161 | BH4: =SUM(L4,AJ4) -> 403 | BI4: =SUM(M4,AK4) -> 151 | BJ4: =SUM(N4,AL4) -> 23 | BK4: =IF(BB4>0,SUM(BF4,BG4,BH4,BI4,BJ4),"") -> 750 | BL4: =B4&$BM$1 -> 08.05.2026MATHS | BM4: =SUM(Q4,AO4) -> 122 | BN4: =SUM(R4,AP4) -> 199 | BO4: =SUM(S4,AQ4) -> 402 | BP4: =SUM(T4,AR4) -> 165 | BQ4: =SUM(U4,AS4) -> 23 | BR4: =IF(BB4>0,SUM(BM4,BN4,BO4,BP4,BQ4),"") -> 911 | BS4: =B4&$BT$1 -> 08.05.2026ENGLISH | BT4: =SUM(X4,AV4) -> 122 | BU4: =SUM(Y4,AW4) -> 241 | BV4: =SUM(Z4,AX4) -> 392 | BW4: =SUM(AA4,AY4) -> 133 | BX4: =SUM(AB4,AZ4) -> 23 | BY4: =IF(BB4>0,SUM(BT4,BU4,BV4,BW4,BX4),"") -> 911 | BZ4: =IF(E4="","",VLOOKUP(B4&$BZ$1,FLNTRANSPOSE!$F$3:$DP$102,105,0)) -> 0 | CA4: =IF(E4="","",VLOOKUP(B4&$BZ$1,FLNTRANSPOSE!$F$3:$DP$102,107,0)) -> 28 | CB4: =IF(E4="","",VLOOKUP(B4&$BZ$1,FLNTRANSPOSE!$F$3:$DP$102,109,0)) -> 5 | CC4: =IF(E4="","",VLOOKUP(B4&$BZ$1,FLNTRANSPOSE!$F$3:$DP$102,111,0)) -> 3 | CD4: =IF(E4="","",VLOOKUP(B4&$BZ$1,FLNTRANSPOSE!$F$3:$DP$102,113,0)) -> 0 | CE4: =IF(E4="","",VLOOKUP(B4&$BZ$1,FLNTRANSPOSE!$F$3:$DP$102,115,0)) -> 3 | CF4: =IF(E4="","",SUM(BZ4,CA4,CB4,CC4,CD4,CE4)) -> 39 | CG4: =IF(E4="","",VLOOKUP(B4&$CG$1,FLNTRANSPOSE!$F$3:$DP$102,105,0)) -> 0 | CH4: =IF(E4="","",VLOOKUP(B4&$CG$1,FLNTRANSPOSE!$F$3:$DP$102,107,0)) -> 0 | CI4: =IF(E4="","",VLOOKUP(B4&$CG$1,FLNTRANSPOSE!$F$3:$DP$102,109,0)) -> 27 | CJ4: =IF(E4="","",VLOOKUP(B4&$CG$1,FLNTRANSPOSE!$F$3:$DP$102,111,0)) -> 9 | CK4: =IF(E4="","",VLOOKUP(B4&$CG$1,FLNTRANSPOSE!$F$3:$DP$102,113,0)) -> 0 | CL4: =IF(E4="","",VLOOKUP(B4&$CG$1,FLNTRANSPOSE!$F$3:$DP$102,115,0)) -> 3 | CM4: =IF(E4="","",SUM(CG4,CH4,CI4,CJ4,CK4,CL4)) -> 39 | CN4: =IF(E4="","",VLOOKUP(B4&$CN$1,FLNTRANSPOSE!$F$3:$DP$102,105,0)) -> 0 | CO4: =IF(E4="","",VLOOKUP(B4&$CN$1,FLNTRANSPOSE!$F$3:$DP$102,107,0)) -> 31 | CP4: =IF(E4="","",VLOOKUP(B4&$CN$1,FLNTRANSPOSE!$F$3:$DP$102,109,0)) -> 5 | CQ4: =IF(E4="","",VLOOKUP(B4&$CN$1,FLNTRANSPOSE!$F$3:$DP$102,111,0)) -> 0 | CR4: =IF(E4="","",VLOOKUP(B4&$CN$1,FLNTRANSPOSE!$F$3:$DP$102,113,0)) -> 0 | CS4: =IF(E4="","",VLOOKUP(B4&$CN$1,FLNTRANSPOSE!$F$3:$DP$102,115,0)) -> 3 | CT4: =IF(E4="","",SUM(CN4,CO4,CP4,CQ4,CR4,CS4)) -> 39
A5: 3 | B5: 15.07.2026 | C5: 39 | D5: 3 | E5: =IF(C5>0,MIN(C5-D5),"") -> 36 | G5: 0 | H5: =IF(F5>0,MIN(F5-G5),"") | I5: =B5&$J$1 -> 15.07.2026HINDI | J5: 0 | K5: 24 | L5: 15 | M5: 0 | N5: 0 | O5: =IF(F5>0,SUM(J5,K5,L5,M5,N5),"") | P5: =B5&$Q$1 -> 15.07.2026MATHS | Q5: 129 | R5: 74 | S5: 23 | T5: 5 | U5: 0 | V5: =IF(F5>0,SUM(Q5,R5,S5,T5,U5),"") | W5: =B5&$X$1 -> 15.07.2026ENGLISH | X5: 131 | Y5: 75 | Z5: 25 | AA5: 0 | AB5: 0 | AC5: =IF(F5>0,SUM(X5,Y5,Z5,AA5,AB5),"") | AD5: 756 | AE5: 0 | AF5: =IF(AD5>0,MIN(AD5-AE5),"") -> 756 | AG5: =B5&$AH$1 -> 15.07.2026HINDI | AH5: 9 | AI5: 130 | AJ5: 434 | AK5: 154 | AL5: 29 | AM5: =IF(AD5>0,SUM(AH5,AI5,AJ5,AK5,AL5),"") -> 756 | AN5: =B5&$AO$1 -> 15.07.2026MATHS | AO5: 9 | AP5: 117 | AQ5: 416 | AR5: 189 | AS5: 25 | AT5: =IF(AD5>0,SUM(AO5,AP5,AQ5,AR5,AS5),"") -> 756 | AU5: =B5&$AV$1 -> 15.07.2026ENGLISH | AV5: 9 | AW5: 179 | AX5: 411 | AY5: 133 | AZ5: 24 | BA5: =IF(AD5>0,SUM(AV5,AW5,AX5,AY5,AZ5),"") -> 756 | BB5: =SUM(F5,AD5) -> 756 | BC5: =SUM(G5,AE5) -> 0 | BD5: =IF(BB5>0,MIN(BB5-BC5),"") -> 756 | BE5: =B5&$BF$1 -> 15.07.2026HINDI | BF5: =SUM(J5,AH5) -> 9 | BG5: =SUM(K5,AI5) -> 154 | BH5: =SUM(L5,AJ5) -> 449 | BI5: =SUM(M5,AK5) -> 154 | BJ5: =SUM(N5,AL5) -> 29 | BK5: =IF(BB5>0,SUM(BF5,BG5,BH5,BI5,BJ5),"") -> 795 | BL5: =B5&$BM$1 -> 15.07.2026MATHS | BM5: =SUM(Q5,AO5) -> 138 | BN5: =SUM(R5,AP5) -> 191 | BO5: =SUM(S5,AQ5) -> 439 | BP5: =SUM(T5,AR5) -> 194 | BQ5: =SUM(U5,AS5) -> 25 | BR5: =IF(BB5>0,SUM(BM5,BN5,BO5,BP5,BQ5),"") -> 987 | BS5: =B5&$BT$1 -> 15.07.2026ENGLISH | BT5: =SUM(X5,AV5) -> 140 | BU5: =SUM(Y5,AW5) -> 254 | BV5: =SUM(Z5,AX5) -> 436 | BW5: =SUM(AA5,AY5) -> 133 | BX5: =SUM(AB5,AZ5) -> 24 | BY5: =IF(BB5>0,SUM(BT5,BU5,BV5,BW5,BX5),"") -> 987 | BZ5: =IF(E5="","",VLOOKUP(B5&$BZ$1,FLNTRANSPOSE!$F$3:$DP$102,105,0)) -> 0 | CA5: =IF(E5="","",VLOOKUP(B5&$BZ$1,FLNTRANSPOSE!$F$3:$DP$102,107,0)) -> 28 | CB5: =IF(E5="","",VLOOKUP(B5&$BZ$1,FLNTRANSPOSE!$F$3:$DP$102,109,0)) -> 5 | CC5: =IF(E5="","",VLOOKUP(B5&$BZ$1,FLNTRANSPOSE!$F$3:$DP$102,111,0)) -> 3 | CD5: =IF(E5="","",VLOOKUP(B5&$BZ$1,FLNTRANSPOSE!$F$3:$DP$102,113,0)) -> 0 | CE5: =IF(E5="","",VLOOKUP(B5&$BZ$1,FLNTRANSPOSE!$F$3:$DP$102,115,0)) -> 3 | CF5: =IF(E5="","",SUM(BZ5,CA5,CB5,CC5,CD5,CE5)) -> 39 | CG5: =IF(E5="","",VLOOKUP(B5&$CG$1,FLNTRANSPOSE!$F$3:$DP$102,105,0)) -> 0 | CH5: =IF(E5="","",VLOOKUP(B5&$CG$1,FLNTRANSPOSE!$F$3:$DP$102,107,0)) -> 0 | CI5: =IF(E5="","",VLOOKUP(B5&$CG$1,FLNTRANSPOSE!$F$3:$DP$102,109,0)) -> 27 | CJ5: =IF(E5="","",VLOOKUP(B5&$CG$1,FLNTRANSPOSE!$F$3:$DP$102,111,0)) -> 9 | CK5: =IF(E5="","",VLOOKUP(B5&$CG$1,FLNTRANSPOSE!$F$3:$DP$102,113,0)) -> 0 | CL5: =IF(E5="","",VLOOKUP(B5&$CG$1,FLNTRANSPOSE!$F$3:$DP$102,115,0)) -> 3 | CM5: =IF(E5="","",SUM(CG5,CH5,CI5,CJ5,CK5,CL5)) -> 39 | CN5: =IF(E5="","",VLOOKUP(B5&$CN$1,FLNTRANSPOSE!$F$3:$DP$102,105,0)) -> 0 | CO5: =IF(E5="","",VLOOKUP(B5&$CN$1,FLNTRANSPOSE!$F$3:$DP$102,107,0)) -> 31 | CP5: =IF(E5="","",VLOOKUP(B5&$CN$1,FLNTRANSPOSE!$F$3:$DP$102,109,0)) -> 5 | CQ5: =IF(E5="","",VLOOKUP(B5&$CN$1,FLNTRANSPOSE!$F$3:$DP$102,111,0)) -> 0 | CR5: =IF(E5="","",VLOOKUP(B5&$CN$1,FLNTRANSPOSE!$F$3:$DP$102,113,0)) -> 0 | CS5: =IF(E5="","",VLOOKUP(B5&$CN$1,FLNTRANSPOSE!$F$3:$DP$102,115,0)) -> 3 | CT5: =IF(E5="","",SUM(CN5,CO5,CP5,CQ5,CR5,CS5)) -> 39
A6: 4 | B6: 31.07.2026 | C6: 39 | D6: 3 | E6: =IF(C6>0,MIN(C6-D6),"") -> 36 | G6: 0 | H6: =IF(F6>0,MIN(F6-G6),"") | I6: =B6&$J$1 -> 31.07.2026HINDI | J6: 0 | K6: 24 | L6: 15 | M6: 0 | N6: 0 | O6: =IF(F6>0,SUM(J6,K6,L6,M6,N6),"") | P6: =B6&$Q$1 -> 31.07.2026MATHS | Q6: 129 | R6: 99 | S6: 23 | T6: 5 | U6: 0 | V6: =IF(F6>0,SUM(Q6,R6,S6,T6,U6),"") | W6: =B6&$X$1 -> 31.07.2026ENGLISH | X6: 131 | Y6: 100 | Z6: 25 | AA6: 0 | AB6: 0 | AC6: =IF(F6>0,SUM(X6,Y6,Z6,AA6,AB6),"") | AD6: 778 | AE6: 0 | AF6: =IF(AD6>0,MIN(AD6-AE6),"") -> 778 | AG6: =B6&$AH$1 -> 31.07.2026HINDI | AH6: 9 | AI6: 128 | AJ6: 462 | AK6: 150 | AL6: 29 | AM6: =IF(AD6>0,SUM(AH6,AI6,AJ6,AK6,AL6),"") -> 778 | AN6: =B6&$AO$1 -> 31.07.2026MATHS | AO6: 9 | AP6: 115 | AQ6: 444 | AR6: 185 | AS6: 25 | AT6: =IF(AD6>0,SUM(AO6,AP6,AQ6,AR6,AS6),"") -> 778 | AU6: =B6&$AV$1 -> 31.07.2026ENGLISH | AV6: 9 | AW6: 176 | AX6: 440 | AY6: 129 | AZ6: 24 | BA6: =IF(AD6>0,SUM(AV6,AW6,AX6,AY6,AZ6),"") -> 778 | BB6: =SUM(F6,AD6) -> 778 | BC6: =SUM(G6,AE6) -> 0 | BD6: =IF(BB6>0,MIN(BB6-BC6),"") -> 778 | BE6: =B6&$BF$1 -> 31.07.2026HINDI | BF6: =SUM(J6,AH6) -> 9 | BG6: =SUM(K6,AI6) -> 152 | BH6: =SUM(L6,AJ6) -> 477 | BI6: =SUM(M6,AK6) -> 150 | BJ6: =SUM(N6,AL6) -> 29 | BK6: =IF(BB6>0,SUM(BF6,BG6,BH6,BI6,BJ6),"") -> 817 | BL6: =B6&$BM$1 -> 31.07.2026MATHS | BM6: =SUM(Q6,AO6) -> 138 | BN6: =SUM(R6,AP6) -> 214 | BO6: =SUM(S6,AQ6) -> 467 | BP6: =SUM(T6,AR6) -> 190 | BQ6: =SUM(U6,AS6) -> 25 | BR6: =IF(BB6>0,SUM(BM6,BN6,BO6,BP6,BQ6),"") -> 1034 | BS6: =B6&$BT$1 -> 31.07.2026ENGLISH | BT6: =SUM(X6,AV6) -> 140 | BU6: =SUM(Y6,AW6) -> 276 | BV6: =SUM(Z6,AX6) -> 465 | BW6: =SUM(AA6,AY6) -> 129 | BX6: =SUM(AB6,AZ6) -> 24 | BY6: =IF(BB6>0,SUM(BT6,BU6,BV6,BW6,BX6),"") -> 1034 | BZ6: =IF(E6="","",VLOOKUP(B6&$BZ$1,FLNTRANSPOSE!$F$3:$DP$102,105,0)) -> 0 | CA6: =IF(E6="","",VLOOKUP(B6&$BZ$1,FLNTRANSPOSE!$F$3:$DP$102,107,0)) -> 28 | CB6: =IF(E6="","",VLOOKUP(B6&$BZ$1,FLNTRANSPOSE!$F$3:$DP$102,109,0)) -> 5 | CC6: =IF(E6="","",VLOOKUP(B6&$BZ$1,FLNTRANSPOSE!$F$3:$DP$102,111,0)) -> 3 | CD6: =IF(E6="","",VLOOKUP(B6&$BZ$1,FLNTRANSPOSE!$F$3:$DP$102,113,0)) -> 0 | CE6: =IF(E6="","",VLOOKUP(B6&$BZ$1,FLNTRANSPOSE!$F$3:$DP$102,115,0)) -> 3 | CF6: =IF(E6="","",SUM(BZ6,CA6,CB6,CC6,CD6,CE6)) -> 39 | CG6: =IF(E6="","",VLOOKUP(B6&$CG$1,FLNTRANSPOSE!$F$3:$DP$102,105,0)) -> 0 | CH6: =IF(E6="","",VLOOKUP(B6&$CG$1,FLNTRANSPOSE!$F$3:$DP$102,107,0)) -> 0 | CI6: =IF(E6="","",VLOOKUP(B6&$CG$1,FLNTRANSPOSE!$F$3:$DP$102,109,0)) -> 27 | CJ6: =IF(E6="","",VLOOKUP(B6&$CG$1,FLNTRANSPOSE!$F$3:$DP$102,111,0)) -> 9 | CK6: =IF(E6="","",VLOOKUP(B6&$CG$1,FLNTRANSPOSE!$F$3:$DP$102,113,0)) -> 0 | CL6: =IF(E6="","",VLOOKUP(B6&$CG$1,FLNTRANSPOSE!$F$3:$DP$102,115,0)) -> 3 | CM6: =IF(E6="","",SUM(CG6,CH6,CI6,CJ6,CK6,CL6)) -> 39 | CN6: =IF(E6="","",VLOOKUP(B6&$CN$1,FLNTRANSPOSE!$F$3:$DP$102,105,0)) -> 0 | CO6: =IF(E6="","",VLOOKUP(B6&$CN$1,FLNTRANSPOSE!$F$3:$DP$102,107,0)) -> 31 | CP6: =IF(E6="","",VLOOKUP(B6&$CN$1,FLNTRANSPOSE!$F$3:$DP$102,109,0)) -> 5 | CQ6: =IF(E6="","",VLOOKUP(B6&$CN$1,FLNTRANSPOSE!$F$3:$DP$102,111,0)) -> 0 | CR6: =IF(E6="","",VLOOKUP(B6&$CN$1,FLNTRANSPOSE!$F$3:$DP$102,113,0)) -> 0 | CS6: =IF(E6="","",VLOOKUP(B6&$CN$1,FLNTRANSPOSE!$F$3:$DP$102,115,0)) -> 3 | CT6: =IF(E6="","",SUM(CN6,CO6,CP6,CQ6,CR6,CS6)) -> 39
A7: 5 | B7: 17.08.2026 | C7: 39 | D7: 3 | E7: =IF(C7>0,MIN(C7-D7),"") -> 36 | H7: =IF(F7>0,MIN(F7-G7),"") | I7: =B7&$J$1 -> 17.08.2026HINDI | J7: 0 | K7: 18 | L7: 20 | M7: 1 | N7: 0 | O7: =IF(F7>0,SUM(J7,K7,L7,M7,N7),"") | P7: =B7&$Q$1 -> 17.08.2026MATHS | V7: =IF(F7>0,SUM(Q7,R7,S7,T7,U7),"") | W7: =B7&$X$1 -> 17.08.2026ENGLISH | AC7: =IF(F7>0,SUM(X7,Y7,Z7,AA7,AB7),"") | AF7: =IF(AD7>0,MIN(AD7-AE7),"") | AG7: =B7&$AH$1 -> 17.08.2026HINDI | AM7: =IF(AD7>0,SUM(AH7,AI7,AJ7,AK7,AL7),"") | AN7: =B7&$AO$1 -> 17.08.2026MATHS | AT7: =IF(AD7>0,SUM(AO7,AP7,AQ7,AR7,AS7),"") | AU7: =B7&$AV$1 -> 17.08.2026ENGLISH | BA7: =IF(AD7>0,SUM(AV7,AW7,AX7,AY7,AZ7),"") | BB7: =SUM(F7,AD7) -> 0 | BC7: =SUM(G7,AE7) -> 0 | BD7: =IF(BB7>0,MIN(BB7-BC7),"") | BE7: =B7&$BF$1 -> 17.08.2026HINDI | BF7: =SUM(J7,AH7) -> 0 | BG7: =SUM(K7,AI7) -> 18 | BH7: =SUM(L7,AJ7) -> 20 | BI7: =SUM(M7,AK7) -> 1 | BJ7: =SUM(N7,AL7) -> 0 | BK7: =IF(BB7>0,SUM(BF7,BG7,BH7,BI7,BJ7),"") | BL7: =B7&$BM$1 -> 17.08.2026MATHS | BM7: =SUM(Q7,AO7) -> 0 | BN7: =SUM(R7,AP7) -> 0 | BO7: =SUM(S7,AQ7) -> 0 | BP7: =SUM(T7,AR7) -> 0 | BQ7: =SUM(U7,AS7) -> 0 | BR7: =IF(BB7>0,SUM(BM7,BN7,BO7,BP7,BQ7),"") | BS7: =B7&$BT$1 -> 17.08.2026ENGLISH | BT7: =SUM(X7,AV7) -> 0 | BU7: =SUM(Y7,AW7) -> 0 | BV7: =SUM(Z7,AX7) -> 0 | BW7: =SUM(AA7,AY7) -> 0 | BX7: =SUM(AB7,AZ7) -> 0 | BY7: =IF(BB7>0,SUM(BT7,BU7,BV7,BW7,BX7),"") | BZ7: =IF(E7="","",VLOOKUP(B7&$BZ$1,FLNTRANSPOSE!$F$3:$DP$102,105,0)) -> 0 | CA7: =IF(E7="","",VLOOKUP(B7&$BZ$1,FLNTRANSPOSE!$F$3:$DP$102,107,0)) -> 28 | CB7: =IF(E7="","",VLOOKUP(B7&$BZ$1,FLNTRANSPOSE!$F$3:$DP$102,109,0)) -> 5 | CC7: =IF(E7="","",VLOOKUP(B7&$BZ$1,FLNTRANSPOSE!$F$3:$DP$102,111,0)) -> 3 | CD7: =IF(E7="","",VLOOKUP(B7&$BZ$1,FLNTRANSPOSE!$F$3:$DP$102,113,0)) -> 0 | CE7: =IF(E7="","",VLOOKUP(B7&$BZ$1,FLNTRANSPOSE!$F$3:$DP$102,115,0)) -> 3 | CF7: =IF(E7="","",SUM(BZ7,CA7,CB7,CC7,CD7,CE7)) -> 39 | CG7: =IF(E7="","",VLOOKUP(B7&$CG$1,FLNTRANSPOSE!$F$3:$DP$102,105,0)) -> 0 | CH7: =IF(E7="","",VLOOKUP(B7&$CG$1,FLNTRANSPOSE!$F$3:$DP$102,107,0)) -> 0 | CI7: =IF(E7="","",VLOOKUP(B7&$CG$1,FLNTRANSPOSE!$F$3:$DP$102,109,0)) -> 27 | CJ7: =IF(E7="","",VLOOKUP(B7&$CG$1,FLNTRANSPOSE!$F$3:$DP$102,111,0)) -> 9 | CK7: =IF(E7="","",VLOOKUP(B7&$CG$1,FLNTRANSPOSE!$F$3:$DP$102,113,0)) -> 0 | CL7: =IF(E7="","",VLOOKUP(B7&$CG$1,FLNTRANSPOSE!$F$3:$DP$102,115,0)) -> 3 | CM7: =IF(E7="","",SUM(CG7,CH7,CI7,CJ7,CK7,CL7)) -> 39 | CN7: =IF(E7="","",VLOOKUP(B7&$CN$1,FLNTRANSPOSE!$F$3:$DP$102,105,0)) -> 0 | CO7: =IF(E7="","",VLOOKUP(B7&$CN$1,FLNTRANSPOSE!$F$3:$DP$102,107,0)) -> 31 | CP7: =IF(E7="","",VLOOKUP(B7&$CN$1,FLNTRANSPOSE!$F$3:$DP$102,109,0)) -> 5 | CQ7: =IF(E7="","",VLOOKUP(B7&$CN$1,FLNTRANSPOSE!$F$3:$DP$102,111,0)) -> 0 | CR7: =IF(E7="","",VLOOKUP(B7&$CN$1,FLNTRANSPOSE!$F$3:$DP$102,113,0)) -> 0 | CS7: =IF(E7="","",VLOOKUP(B7&$CN$1,FLNTRANSPOSE!$F$3:$DP$102,115,0)) -> 3 | CT7: =IF(E7="","",SUM(CN7,CO7,CP7,CQ7,CR7,CS7)) -> 39
A8: 6 | B8: 31.08.2026 | C8: 39 | D8: 3 | E8: =IF(C8>0,MIN(C8-D8),"") -> 36 | H8: =IF(F8>0,MIN(F8-G8),"") | I8: =B8&$J$1 -> 31.08.2026HINDI | O8: =IF(F8>0,SUM(J8,K8,L8,M8,N8),"") | P8: =B8&$Q$1 -> 31.08.2026MATHS | V8: =IF(F8>0,SUM(Q8,R8,S8,T8,U8),"") | W8: =B8&$X$1 -> 31.08.2026ENGLISH | AC8: =IF(F8>0,SUM(X8,Y8,Z8,AA8,AB8),"") | AF8: =IF(AD8>0,MIN(AD8-AE8),"") | AG8: =B8&$AH$1 -> 31.08.2026HINDI | AM8: =IF(AD8>0,SUM(AH8,AI8,AJ8,AK8,AL8),"") | AN8: =B8&$AO$1 -> 31.08.2026MATHS | AT8: =IF(AD8>0,SUM(AO8,AP8,AQ8,AR8,AS8),"") | AU8: =B8&$AV$1 -> 31.08.2026ENGLISH | BA8: =IF(AD8>0,SUM(AV8,AW8,AX8,AY8,AZ8),"") | BB8: =SUM(F8,AD8) -> 0 | BC8: =SUM(G8,AE8) -> 0 | BD8: =IF(BB8>0,MIN(BB8-BC8),"") | BE8: =B8&$BF$1 -> 31.08.2026HINDI | BF8: =SUM(J8,AH8) -> 0 | BG8: =SUM(K8,AI8) -> 0 | BH8: =SUM(L8,AJ8) -> 0 | BI8: =SUM(M8,AK8) -> 0 | BJ8: =SUM(N8,AL8) -> 0 | BK8: =IF(BB8>0,SUM(BF8,BG8,BH8,BI8,BJ8),"") | BL8: =B8&$BM$1 -> 31.08.2026MATHS | BM8: =SUM(Q8,AO8) -> 0 | BN8: =SUM(R8,AP8) -> 0 | BO8: =SUM(S8,AQ8) -> 0 | BP8: =SUM(T8,AR8) -> 0 | BQ8: =SUM(U8,AS8) -> 0 | BR8: =IF(BB8>0,SUM(BM8,BN8,BO8,BP8,BQ8),"") | BS8: =B8&$BT$1 -> 31.08.2026ENGLISH | BT8: =SUM(X8,AV8) -> 0 | BU8: =SUM(Y8,AW8) -> 0 | BV8: =SUM(Z8,AX8) -> 0 | BW8: =SUM(AA8,AY8) -> 0 | BX8: =SUM(AB8,AZ8) -> 0 | BY8: =IF(BB8>0,SUM(BT8,BU8,BV8,BW8,BX8),"") | BZ8: =IF(E8="","",VLOOKUP(B8&$BZ$1,FLNTRANSPOSE!$F$3:$DP$102,105,0)) -> 0 | CA8: =IF(E8="","",VLOOKUP(B8&$BZ$1,FLNTRANSPOSE!$F$3:$DP$102,107,0)) -> 16 | CB8: =IF(E8="","",VLOOKUP(B8&$BZ$1,FLNTRANSPOSE!$F$3:$DP$102,109,0)) -> 12 | CC8: =IF(E8="","",VLOOKUP(B8&$BZ$1,FLNTRANSPOSE!$F$3:$DP$102,111,0)) -> 8 | CD8: =IF(E8="","",VLOOKUP(B8&$BZ$1,FLNTRANSPOSE!$F$3:$DP$102,113,0)) -> 0 | CE8: =IF(E8="","",VLOOKUP(B8&$BZ$1,FLNTRANSPOSE!$F$3:$DP$102,115,0)) -> 3 | CF8: =IF(E8="","",SUM(BZ8,CA8,CB8,CC8,CD8,CE8)) -> 39 | CG8: =IF(E8="","",VLOOKUP(B8&$CG$1,FLNTRANSPOSE!$F$3:$DP$102,105,0)) -> 0 | CH8: =IF(E8="","",VLOOKUP(B8&$CG$1,FLNTRANSPOSE!$F$3:$DP$102,107,0)) -> 0 | CI8: =IF(E8="","",VLOOKUP(B8&$CG$1,FLNTRANSPOSE!$F$3:$DP$102,109,0)) -> 23 | CJ8: =IF(E8="","",VLOOKUP(B8&$CG$1,FLNTRANSPOSE!$F$3:$DP$102,111,0)) -> 13 | CK8: =IF(E8="","",VLOOKUP(B8&$CG$1,FLNTRANSPOSE!$F$3:$DP$102,113,0)) -> 0 | CL8: =IF(E8="","",VLOOKUP(B8&$CG$1,FLNTRANSPOSE!$F$3:$DP$102,115,0)) -> 3 | CM8: =IF(E8="","",SUM(CG8,CH8,CI8,CJ8,CK8,CL8)) -> 39 | CN8: =IF(E8="","",VLOOKUP(B8&$CN$1,FLNTRANSPOSE!$F$3:$DP$102,105,0)) -> 0 | CO8: =IF(E8="","",VLOOKUP(B8&$CN$1,FLNTRANSPOSE!$F$3:$DP$102,107,0)) -> 27 | CP8: =IF(E8="","",VLOOKUP(B8&$CN$1,FLNTRANSPOSE!$F$3:$DP$102,109,0)) -> 6 | CQ8: =IF(E8="","",VLOOKUP(B8&$CN$1,FLNTRANSPOSE!$F$3:$DP$102,111,0)) -> 3 | CR8: =IF(E8="","",VLOOKUP(B8&$CN$1,FLNTRANSPOSE!$F$3:$DP$102,113,0)) -> 0 | CS8: =IF(E8="","",VLOOKUP(B8&$CN$1,FLNTRANSPOSE!$F$3:$DP$102,115,0)) -> 3 | CT8: =IF(E8="","",SUM(CN8,CO8,CP8,CQ8,CR8,CS8)) -> 39
A9: 7 | C9: 0 | E9: =IF(C9>0,MIN(C9-D9),"") | H9: =IF(F9>0,MIN(F9-G9),"") | I9: =B9&$J$1 -> HINDI | O9: =IF(F9>0,SUM(J9,K9,L9,M9,N9),"") | P9: =B9&$Q$1 -> MATHS | V9: =IF(F9>0,SUM(Q9,R9,S9,T9,U9),"") | W9: =B9&$X$1 -> ENGLISH | AC9: =IF(F9>0,SUM(X9,Y9,Z9,AA9,AB9),"") | AF9: =IF(AD9>0,MIN(AD9-AE9),"") | AG9: =B9&$AH$1 -> HINDI | AM9: =IF(AD9>0,SUM(AH9,AI9,AJ9,AK9,AL9),"") | AN9: =B9&$AO$1 -> MATHS | AT9: =IF(AD9>0,SUM(AO9,AP9,AQ9,AR9,AS9),"") | AU9: =B9&$AV$1 -> ENGLISH | BA9: =IF(AD9>0,SUM(AV9,AW9,AX9,AY9,AZ9),"") | BB9: =SUM(F9,AD9) -> 0 | BC9: =SUM(G9,AE9) -> 0 | BD9: =IF(BB9>0,MIN(BB9-BC9),"") | BE9: =B9&$BF$1 -> HINDI | BF9: =SUM(J9,AH9) -> 0 | BG9: =SUM(K9,AI9) -> 0 | BH9: =SUM(L9,AJ9) -> 0 | BI9: =SUM(M9,AK9) -> 0 | BJ9: =SUM(N9,AL9) -> 0 | BK9: =IF(BB9>0,SUM(BF9,BG9,BH9,BI9,BJ9),"") | BL9: =B9&$BM$1 -> MATHS | BM9: =SUM(Q9,AO9) -> 0 | BN9: =SUM(R9,AP9) -> 0 | BO9: =SUM(S9,AQ9) -> 0 | BP9: =SUM(T9,AR9) -> 0 | BQ9: =SUM(U9,AS9) -> 0 | BR9: =IF(BB9>0,SUM(BM9,BN9,BO9,BP9,BQ9),"") | BS9: =B9&$BT$1 -> ENGLISH | BT9: =SUM(X9,AV9) -> 0 | BU9: =SUM(Y9,AW9) -> 0 | BV9: =SUM(Z9,AX9) -> 0 | BW9: =SUM(AA9,AY9) -> 0 | BX9: =SUM(AB9,AZ9) -> 0 | BY9: =IF(BB9>0,SUM(BT9,BU9,BV9,BW9,BX9),"") | BZ9: =IF(E9="","",VLOOKUP(B9&$BZ$1,FLNTRANSPOSE!$F$3:$DP$102,105,0)) | CA9: =IF(E9="","",VLOOKUP(B9&$BZ$1,FLNTRANSPOSE!$F$3:$DP$102,107,0)) | CB9: =IF(E9="","",VLOOKUP(B9&$BZ$1,FLNTRANSPOSE!$F$3:$DP$102,109,0)) | CC9: =IF(E9="","",VLOOKUP(B9&$BZ$1,FLNTRANSPOSE!$F$3:$DP$102,111,0)) | CD9: =IF(E9="","",VLOOKUP(B9&$BZ$1,FLNTRANSPOSE!$F$3:$DP$102,113,0)) | CE9: =IF(E9="","",VLOOKUP(B9&$BZ$1,FLNTRANSPOSE!$F$3:$DP$102,115,0)) | CF9: =IF(E9="","",SUM(BZ9,CA9,CB9,CC9,CD9,CE9)) | CG9: =IF(E9="","",VLOOKUP(B9&$CG$1,FLNTRANSPOSE!$F$3:$DP$102,105,0)) | CH9: =IF(E9="","",VLOOKUP(B9&$CG$1,FLNTRANSPOSE!$F$3:$DP$102,107,0)) | CI9: =IF(E9="","",VLOOKUP(B9&$CG$1,FLNTRANSPOSE!$F$3:$DP$102,109,0)) | CJ9: =IF(E9="","",VLOOKUP(B9&$CG$1,FLNTRANSPOSE!$F$3:$DP$102,111,0)) | CK9: =IF(E9="","",VLOOKUP(B9&$CG$1,FLNTRANSPOSE!$F$3:$DP$102,113,0)) | CL9: =IF(E9="","",VLOOKUP(B9&$CG$1,FLNTRANSPOSE!$F$3:$DP$102,115,0)) | CM9: =IF(E9="","",SUM(CG9,CH9,CI9,CJ9,CK9,CL9)) | CN9: =IF(E9="","",VLOOKUP(B9&$CN$1,FLNTRANSPOSE!$F$3:$DP$102,105,0)) | CO9: =IF(E9="","",VLOOKUP(B9&$CN$1,FLNTRANSPOSE!$F$3:$DP$102,107,0)) | CP9: =IF(E9="","",VLOOKUP(B9&$CN$1,FLNTRANSPOSE!$F$3:$DP$102,109,0)) | CQ9: =IF(E9="","",VLOOKUP(B9&$CN$1,FLNTRANSPOSE!$F$3:$DP$102,111,0)) | CR9: =IF(E9="","",VLOOKUP(B9&$CN$1,FLNTRANSPOSE!$F$3:$DP$102,113,0)) | CS9: =IF(E9="","",VLOOKUP(B9&$CN$1,FLNTRANSPOSE!$F$3:$DP$102,115,0)) | CT9: =IF(E9="","",SUM(CN9,CO9,CP9,CQ9,CR9,CS9))
A10: 8 | E10: =IF(C10>0,MIN(C10-D10),"") | H10: =IF(F10>0,MIN(F10-G10),"") | I10: =B10&$J$1 -> HINDI | O10: =IF(F10>0,SUM(J10,K10,L10,M10,N10),"") | P10: =B10&$Q$1 -> MATHS | V10: =IF(F10>0,SUM(Q10,R10,S10,T10,U10),"") | W10: =B10&$X$1 -> ENGLISH | AC10: =IF(F10>0,SUM(X10,Y10,Z10,AA10,AB10),"") | AF10: =IF(AD10>0,MIN(AD10-AE10),"") | AG10: =B10&$AH$1 -> HINDI | AM10: =IF(AD10>0,SUM(AH10,AI10,AJ10,AK10,AL10),"") | AN10: =B10&$AO$1 -> MATHS | AT10: =IF(AD10>0,SUM(AO10,AP10,AQ10,AR10,AS10),"") | AU10: =B10&$AV$1 -> ENGLISH | BA10: =IF(AD10>0,SUM(AV10,AW10,AX10,AY10,AZ10),"") | BB10: =SUM(F10,AD10) -> 0 | BC10: =SUM(G10,AE10) -> 0 | BD10: =IF(BB10>0,MIN(BB10-BC10),"") | BE10: =B10&$BF$1 -> HINDI | BF10: =SUM(J10,AH10) -> 0 | BG10: =SUM(K10,AI10) -> 0 | BH10: =SUM(L10,AJ10) -> 0 | BI10: =SUM(M10,AK10) -> 0 | BJ10: =SUM(N10,AL10) -> 0 | BK10: =IF(BB10>0,SUM(BF10,BG10,BH10,BI10,BJ10),"") | BL10: =B10&$BM$1 -> MATHS | BM10: =SUM(Q10,AO10) -> 0 | BN10: =SUM(R10,AP10) -> 0 | BO10: =SUM(S10,AQ10) -> 0 | BP10: =SUM(T10,AR10) -> 0 | BQ10: =SUM(U10,AS10) -> 0 | BR10: =IF(BB10>0,SUM(BM10,BN10,BO10,BP10,BQ10),"") | BS10: =B10&$BT$1 -> ENGLISH | BT10: =SUM(X10,AV10) -> 0 | BU10: =SUM(Y10,AW10) -> 0 | BV10: =SUM(Z10,AX10) -> 0 | BW10: =SUM(AA10,AY10) -> 0 | BX10: =SUM(AB10,AZ10) -> 0 | BY10: =IF(BB10>0,SUM(BT10,BU10,BV10,BW10,BX10),"") | BZ10: =IF(E10="","",VLOOKUP(B10&$BZ$1,FLNTRANSPOSE!$F$3:$DP$102,105,0)) | CA10: =IF(E10="","",VLOOKUP(B10&$BZ$1,FLNTRANSPOSE!$F$3:$DP$102,107,0)) | CB10: =IF(E10="","",VLOOKUP(B10&$BZ$1,FLNTRANSPOSE!$F$3:$DP$102,109,0)) | CC10: =IF(E10="","",VLOOKUP(B10&$BZ$1,FLNTRANSPOSE!$F$3:$DP$102,111,0)) | CD10: =IF(E10="","",VLOOKUP(B10&$BZ$1,FLNTRANSPOSE!$F$3:$DP$102,113,0)) | CE10: =IF(E10="","",VLOOKUP(B10&$BZ$1,FLNTRANSPOSE!$F$3:$DP$102,115,0)) | CF10: =IF(E10="","",SUM(BZ10,CA10,CB10,CC10,CD10,CE10)) | CG10: =IF(E10="","",VLOOKUP(B10&$CG$1,FLNTRANSPOSE!$F$3:$DP$102,105,0)) | CH10: =IF(E10="","",VLOOKUP(B10&$CG$1,FLNTRANSPOSE!$F$3:$DP$102,107,0)) | CI10: =IF(E10="","",VLOOKUP(B10&$CG$1,FLNTRANSPOSE!$F$3:$DP$102,109,0)) | CJ10: =IF(E10="","",VLOOKUP(B10&$CG$1,FLNTRANSPOSE!$F$3:$DP$102,111,0)) | CK10: =IF(E10="","",VLOOKUP(B10&$CG$1,FLNTRANSPOSE!$F$3:$DP$102,113,0)) | CL10: =IF(E10="","",VLOOKUP(B10&$CG$1,FLNTRANSPOSE!$F$3:$DP$102,115,0)) | CM10: =IF(E10="","",SUM(CG10,CH10,CI10,CJ10,CK10,CL10)) | CN10: =IF(E10="","",VLOOKUP(B10&$CN$1,FLNTRANSPOSE!$F$3:$DP$102,105,0)) | CO10: =IF(E10="","",VLOOKUP(B10&$CN$1,FLNTRANSPOSE!$F$3:$DP$102,107,0)) | CP10: =IF(E10="","",VLOOKUP(B10&$CN$1,FLNTRANSPOSE!$F$3:$DP$102,109,0)) | CQ10: =IF(E10="","",VLOOKUP(B10&$CN$1,FLNTRANSPOSE!$F$3:$DP$102,111,0)) | CR10: =IF(E10="","",VLOOKUP(B10&$CN$1,FLNTRANSPOSE!$F$3:$DP$102,113,0)) | CS10: =IF(E10="","",VLOOKUP(B10&$CN$1,FLNTRANSPOSE!$F$3:$DP$102,115,0)) | CT10: =IF(E10="","",SUM(CN10,CO10,CP10,CQ10,CR10,CS10))
A11: 9 | E11: =IF(C11>0,MIN(C11-D11),"") | H11: =IF(F11>0,MIN(F11-G11),"") | I11: =B11&$J$1 -> HINDI | O11: =IF(F11>0,SUM(J11,K11,L11,M11,N11),"") | P11: =B11&$Q$1 -> MATHS | V11: =IF(F11>0,SUM(Q11,R11,S11,T11,U11),"") | W11: =B11&$X$1 -> ENGLISH | AC11: =IF(F11>0,SUM(X11,Y11,Z11,AA11,AB11),"") | AF11: =IF(AD11>0,MIN(AD11-AE11),"") | AG11: =B11&$AH$1 -> HINDI | AM11: =IF(AD11>0,SUM(AH11,AI11,AJ11,AK11,AL11),"") | AN11: =B11&$AO$1 -> MATHS | AT11: =IF(AD11>0,SUM(AO11,AP11,AQ11,AR11,AS11),"") | AU11: =B11&$AV$1 -> ENGLISH | BA11: =IF(AD11>0,SUM(AV11,AW11,AX11,AY11,AZ11),"") | BB11: =SUM(F11,AD11) -> 0 | BC11: =SUM(G11,AE11) -> 0 | BD11: =IF(BB11>0,MIN(BB11-BC11),"") | BE11: =B11&$BF$1 -> HINDI | BF11: =SUM(J11,AH11) -> 0 | BG11: =SUM(K11,AI11) -> 0 | BH11: =SUM(L11,AJ11) -> 0 | BI11: =SUM(M11,AK11) -> 0 | BJ11: =SUM(N11,AL11) -> 0 | BK11: =IF(BB11>0,SUM(BF11,BG11,BH11,BI11,BJ11),"") | BL11: =B11&$BM$1 -> MATHS | BM11: =SUM(Q11,AO11) -> 0 | BN11: =SUM(R11,AP11) -> 0 | BO11: =SUM(S11,AQ11) -> 0 | BP11: =SUM(T11,AR11) -> 0 | BQ11: =SUM(U11,AS11) -> 0 | BR11: =IF(BB11>0,SUM(BM11,BN11,BO11,BP11,BQ11),"") | BS11: =B11&$BT$1 -> ENGLISH | BT11: =SUM(X11,AV11) -> 0 | BU11: =SUM(Y11,AW11) -> 0 | BV11: =SUM(Z11,AX11) -> 0 | BW11: =SUM(AA11,AY11) -> 0 | BX11: =SUM(AB11,AZ11) -> 0 | BY11: =IF(BB11>0,SUM(BT11,BU11,BV11,BW11,BX11),"") | BZ11: =IF(E11="","",VLOOKUP(B11&$BZ$1,FLNTRANSPOSE!$F$3:$DP$102,105,0)) | CA11: =IF(E11="","",VLOOKUP(B11&$BZ$1,FLNTRANSPOSE!$F$3:$DP$102,107,0)) | CB11: =IF(E11="","",VLOOKUP(B11&$BZ$1,FLNTRANSPOSE!$F$3:$DP$102,109,0)) | CC11: =IF(E11="","",VLOOKUP(B11&$BZ$1,FLNTRANSPOSE!$F$3:$DP$102,111,0)) | CD11: =IF(E11="","",VLOOKUP(B11&$BZ$1,FLNTRANSPOSE!$F$3:$DP$102,113,0)) | CE11: =IF(E11="","",VLOOKUP(B11&$BZ$1,FLNTRANSPOSE!$F$3:$DP$102,115,0)) | CF11: =IF(E11="","",SUM(BZ11,CA11,CB11,CC11,CD11,CE11)) | CG11: =IF(E11="","",VLOOKUP(B11&$CG$1,FLNTRANSPOSE!$F$3:$DP$102,105,0)) | CH11: =IF(E11="","",VLOOKUP(B11&$CG$1,FLNTRANSPOSE!$F$3:$DP$102,107,0)) | CI11: =IF(E11="","",VLOOKUP(B11&$CG$1,FLNTRANSPOSE!$F$3:$DP$102,109,0)) | CJ11: =IF(E11="","",VLOOKUP(B11&$CG$1,FLNTRANSPOSE!$F$3:$DP$102,111,0)) | CK11: =IF(E11="","",VLOOKUP(B11&$CG$1,FLNTRANSPOSE!$F$3:$DP$102,113,0)) | CL11: =IF(E11="","",VLOOKUP(B11&$CG$1,FLNTRANSPOSE!$F$3:$DP$102,115,0)) | CM11: =IF(E11="","",SUM(CG11,CH11,CI11,CJ11,CK11,CL11)) | CN11: =IF(E11="","",VLOOKUP(B11&$CN$1,FLNTRANSPOSE!$F$3:$DP$102,105,0)) | CO11: =IF(E11="","",VLOOKUP(B11&$CN$1,FLNTRANSPOSE!$F$3:$DP$102,107,0)) | CP11: =IF(E11="","",VLOOKUP(B11&$CN$1,FLNTRANSPOSE!$F$3:$DP$102,109,0)) | CQ11: =IF(E11="","",VLOOKUP(B11&$CN$1,FLNTRANSPOSE!$F$3:$DP$102,111,0)) | CR11: =IF(E11="","",VLOOKUP(B11&$CN$1,FLNTRANSPOSE!$F$3:$DP$102,113,0)) | CS11: =IF(E11="","",VLOOKUP(B11&$CN$1,FLNTRANSPOSE!$F$3:$DP$102,115,0)) | CT11: =IF(E11="","",SUM(CN11,CO11,CP11,CQ11,CR11,CS11))
A12: 10 | E12: =IF(C12>0,MIN(C12-D12),"") | H12: =IF(F12>0,MIN(F12-G12),"") | I12: =B12&$J$1 -> HINDI | O12: =IF(F12>0,SUM(J12,K12,L12,M12,N12),"") | P12: =B12&$Q$1 -> MATHS | V12: =IF(F12>0,SUM(Q12,R12,S12,T12,U12),"") | W12: =B12&$X$1 -> ENGLISH | AC12: =IF(F12>0,SUM(X12,Y12,Z12,AA12,AB12),"") | AF12: =IF(AD12>0,MIN(AD12-AE12),"") | AG12: =B12&$AH$1 -> HINDI | AM12: =IF(AD12>0,SUM(AH12,AI12,AJ12,AK12,AL12),"") | AN12: =B12&$AO$1 -> MATHS | AT12: =IF(AD12>0,SUM(AO12,AP12,AQ12,AR12,AS12),"") | AU12: =B12&$AV$1 -> ENGLISH | BA12: =IF(AD12>0,SUM(AV12,AW12,AX12,AY12,AZ12),"") | BB12: =SUM(F12,AD12) -> 0 | BC12: =SUM(G12,AE12) -> 0 | BD12: =IF(BB12>0,MIN(BB12-BC12),"") | BE12: =B12&$BF$1 -> HINDI | BF12: =SUM(J12,AH12) -> 0 | BG12: =SUM(K12,AI12) -> 0 | BH12: =SUM(L12,AJ12) -> 0 | BI12: =SUM(M12,AK12) -> 0 | BJ12: =SUM(N12,AL12) -> 0 | BK12: =IF(BB12>0,SUM(BF12,BG12,BH12,BI12,BJ12),"") | BL12: =B12&$BM$1 -> MATHS | BM12: =SUM(Q12,AO12) -> 0 | BN12: =SUM(R12,AP12) -> 0 | BO12: =SUM(S12,AQ12) -> 0 | BP12: =SUM(T12,AR12) -> 0 | BQ12: =SUM(U12,AS12) -> 0 | BR12: =IF(BB12>0,SUM(BM12,BN12,BO12,BP12,BQ12),"") | BS12: =B12&$BT$1 -> ENGLISH | BT12: =SUM(X12,AV12) -> 0 | BU12: =SUM(Y12,AW12) -> 0 | BV12: =SUM(Z12,AX12) -> 0 | BW12: =SUM(AA12,AY12) -> 0 | BX12: =SUM(AB12,AZ12) -> 0 | BY12: =IF(BB12>0,SUM(BT12,BU12,BV12,BW12,BX12),"") | BZ12: =IF(E12="","",VLOOKUP(B12&$BZ$1,FLNTRANSPOSE!$F$3:$DP$102,105,0)) | CA12: =IF(E12="","",VLOOKUP(B12&$BZ$1,FLNTRANSPOSE!$F$3:$DP$102,107,0)) | CB12: =IF(E12="","",VLOOKUP(B12&$BZ$1,FLNTRANSPOSE!$F$3:$DP$102,109,0)) | CC12: =IF(E12="","",VLOOKUP(B12&$BZ$1,FLNTRANSPOSE!$F$3:$DP$102,111,0)) | CD12: =IF(E12="","",VLOOKUP(B12&$BZ$1,FLNTRANSPOSE!$F$3:$DP$102,113,0)) | CE12: =IF(E12="","",VLOOKUP(B12&$BZ$1,FLNTRANSPOSE!$F$3:$DP$102,115,0)) | CF12: =IF(E12="","",SUM(BZ12,CA12,CB12,CC12,CD12,CE12)) | CG12: =IF(E12="","",VLOOKUP(B12&$CG$1,FLNTRANSPOSE!$F$3:$DP$102,105,0)) | CH12: =IF(E12="","",VLOOKUP(B12&$CG$1,FLNTRANSPOSE!$F$3:$DP$102,107,0)) | CI12: =IF(E12="","",VLOOKUP(B12&$CG$1,FLNTRANSPOSE!$F$3:$DP$102,109,0)) | CJ12: =IF(E12="","",VLOOKUP(B12&$CG$1,FLNTRANSPOSE!$F$3:$DP$102,111,0)) | CK12: =IF(E12="","",VLOOKUP(B12&$CG$1,FLNTRANSPOSE!$F$3:$DP$102,113,0)) | CL12: =IF(E12="","",VLOOKUP(B12&$CG$1,FLNTRANSPOSE!$F$3:$DP$102,115,0)) | CM12: =IF(E12="","",SUM(CG12,CH12,CI12,CJ12,CK12,CL12)) | CN12: =IF(E12="","",VLOOKUP(B12&$CN$1,FLNTRANSPOSE!$F$3:$DP$102,105,0)) | CO12: =IF(E12="","",VLOOKUP(B12&$CN$1,FLNTRANSPOSE!$F$3:$DP$102,107,0)) | CP12: =IF(E12="","",VLOOKUP(B12&$CN$1,FLNTRANSPOSE!$F$3:$DP$102,109,0)) | CQ12: =IF(E12="","",VLOOKUP(B12&$CN$1,FLNTRANSPOSE!$F$3:$DP$102,111,0)) | CR12: =IF(E12="","",VLOOKUP(B12&$CN$1,FLNTRANSPOSE!$F$3:$DP$102,113,0)) | CS12: =IF(E12="","",VLOOKUP(B12&$CN$1,FLNTRANSPOSE!$F$3:$DP$102,115,0)) | CT12: =IF(E12="","",SUM(CN12,CO12,CP12,CQ12,CR12,CS12))
A13: 11 | E13: =IF(C13>0,MIN(C13-D13),"") | H13: =IF(F13>0,MIN(F13-G13),"") | I13: =B13&$J$1 -> HINDI | O13: =IF(F13>0,SUM(J13,K13,L13,M13,N13),"") | P13: =B13&$Q$1 -> MATHS | V13: =IF(F13>0,SUM(Q13,R13,S13,T13,U13),"") | W13: =B13&$X$1 -> ENGLISH | AC13: =IF(F13>0,SUM(X13,Y13,Z13,AA13,AB13),"") | AF13: =IF(AD13>0,MIN(AD13-AE13),"") | AG13: =B13&$AH$1 -> HINDI | AM13: =IF(AD13>0,SUM(AH13,AI13,AJ13,AK13,AL13),"") | AN13: =B13&$AO$1 -> MATHS | AT13: =IF(AD13>0,SUM(AO13,AP13,AQ13,AR13,AS13),"") | AU13: =B13&$AV$1 -> ENGLISH | BA13: =IF(AD13>0,SUM(AV13,AW13,AX13,AY13,AZ13),"") | BB13: =SUM(F13,AD13) -> 0 | BC13: =SUM(G13,AE13) -> 0 | BD13: =IF(BB13>0,MIN(BB13-BC13),"") | BE13: =B13&$BF$1 -> HINDI | BF13: =SUM(J13,AH13) -> 0 | BG13: =SUM(K13,AI13) -> 0 | BH13: =SUM(L13,AJ13) -> 0 | BI13: =SUM(M13,AK13) -> 0 | BJ13: =SUM(N13,AL13) -> 0 | BK13: =IF(BB13>0,SUM(BF13,BG13,BH13,BI13,BJ13),"") | BL13: =B13&$BM$1 -> MATHS | BM13: =SUM(Q13,AO13) -> 0 | BN13: =SUM(R13,AP13) -> 0 | BO13: =SUM(S13,AQ13) -> 0 | BP13: =SUM(T13,AR13) -> 0 | BQ13: =SUM(U13,AS13) -> 0 | BR13: =IF(BB13>0,SUM(BM13,BN13,BO13,BP13,BQ13),"") | BS13: =B13&$BT$1 -> ENGLISH | BT13: =SUM(X13,AV13) -> 0 | BU13: =SUM(Y13,AW13) -> 0 | BV13: =SUM(Z13,AX13) -> 0 | BW13: =SUM(AA13,AY13) -> 0 | BX13: =SUM(AB13,AZ13) -> 0 | BY13: =IF(BB13>0,SUM(BT13,BU13,BV13,BW13,BX13),"") | BZ13: =IF(E13="","",VLOOKUP(B13&$BZ$1,FLNTRANSPOSE!$F$3:$DP$102,105,0)) | CA13: =IF(E13="","",VLOOKUP(B13&$BZ$1,FLNTRANSPOSE!$F$3:$DP$102,107,0)) | CB13: =IF(E13="","",VLOOKUP(B13&$BZ$1,FLNTRANSPOSE!$F$3:$DP$102,109,0)) | CC13: =IF(E13="","",VLOOKUP(B13&$BZ$1,FLNTRANSPOSE!$F$3:$DP$102,111,0)) | CD13: =IF(E13="","",VLOOKUP(B13&$BZ$1,FLNTRANSPOSE!$F$3:$DP$102,113,0)) | CE13: =IF(E13="","",VLOOKUP(B13&$BZ$1,FLNTRANSPOSE!$F$3:$DP$102,115,0)) | CF13: =IF(E13="","",SUM(BZ13,CA13,CB13,CC13,CD13,CE13)) | CG13: =IF(E13="","",VLOOKUP(B13&$CG$1,FLNTRANSPOSE!$F$3:$DP$102,105,0)) | CH13: =IF(E13="","",VLOOKUP(B13&$CG$1,FLNTRANSPOSE!$F$3:$DP$102,107,0)) | CI13: =IF(E13="","",VLOOKUP(B13&$CG$1,FLNTRANSPOSE!$F$3:$DP$102,109,0)) | CJ13: =IF(E13="","",VLOOKUP(B13&$CG$1,FLNTRANSPOSE!$F$3:$DP$102,111,0)) | CK13: =IF(E13="","",VLOOKUP(B13&$CG$1,FLNTRANSPOSE!$F$3:$DP$102,113,0)) | CL13: =IF(E13="","",VLOOKUP(B13&$CG$1,FLNTRANSPOSE!$F$3:$DP$102,115,0)) | CM13: =IF(E13="","",SUM(CG13,CH13,CI13,CJ13,CK13,CL13)) | CN13: =IF(E13="","",VLOOKUP(B13&$CN$1,FLNTRANSPOSE!$F$3:$DP$102,105,0)) | CO13: =IF(E13="","",VLOOKUP(B13&$CN$1,FLNTRANSPOSE!$F$3:$DP$102,107,0)) | CP13: =IF(E13="","",VLOOKUP(B13&$CN$1,FLNTRANSPOSE!$F$3:$DP$102,109,0)) | CQ13: =IF(E13="","",VLOOKUP(B13&$CN$1,FLNTRANSPOSE!$F$3:$DP$102,111,0)) | CR13: =IF(E13="","",VLOOKUP(B13&$CN$1,FLNTRANSPOSE!$F$3:$DP$102,113,0)) | CS13: =IF(E13="","",VLOOKUP(B13&$CN$1,FLNTRANSPOSE!$F$3:$DP$102,115,0)) | CT13: =IF(E13="","",SUM(CN13,CO13,CP13,CQ13,CR13,CS13))
A14: 12 | E14: =IF(C14>0,MIN(C14-D14),"") | H14: =IF(F14>0,MIN(F14-G14),"") | I14: =B14&$J$1 -> HINDI | O14: =IF(F14>0,SUM(J14,K14,L14,M14,N14),"") | P14: =B14&$Q$1 -> MATHS | V14: =IF(F14>0,SUM(Q14,R14,S14,T14,U14),"") | W14: =B14&$X$1 -> ENGLISH | AC14: =IF(F14>0,SUM(X14,Y14,Z14,AA14,AB14),"") | AF14: =IF(AD14>0,MIN(AD14-AE14),"") | AG14: =B14&$AH$1 -> HINDI | AM14: =IF(AD14>0,SUM(AH14,AI14,AJ14,AK14,AL14),"") | AN14: =B14&$AO$1 -> MATHS | AT14: =IF(AD14>0,SUM(AO14,AP14,AQ14,AR14,AS14),"") | AU14: =B14&$AV$1 -> ENGLISH | BA14: =IF(AD14>0,SUM(AV14,AW14,AX14,AY14,AZ14),"") | BB14: =SUM(F14,AD14) -> 0 | BC14: =SUM(G14,AE14) -> 0 | BD14: =IF(BB14>0,MIN(BB14-BC14),"") | BE14: =B14&$BF$1 -> HINDI | BF14: =SUM(J14,AH14) -> 0 | BG14: =SUM(K14,AI14) -> 0 | BH14: =SUM(L14,AJ14) -> 0 | BI14: =SUM(M14,AK14) -> 0 | BJ14: =SUM(N14,AL14) -> 0 | BK14: =IF(BB14>0,SUM(BF14,BG14,BH14,BI14,BJ14),"") | BL14: =B14&$BM$1 -> MATHS | BM14: =SUM(Q14,AO14) -> 0 | BN14: =SUM(R14,AP14) -> 0 | BO14: =SUM(S14,AQ14) -> 0 | BP14: =SUM(T14,AR14) -> 0 | BQ14: =SUM(U14,AS14) -> 0 | BR14: =IF(BB14>0,SUM(BM14,BN14,BO14,BP14,BQ14),"") | BS14: =B14&$BT$1 -> ENGLISH | BT14: =SUM(X14,AV14) -> 0 | BU14: =SUM(Y14,AW14) -> 0 | BV14: =SUM(Z14,AX14) -> 0 | BW14: =SUM(AA14,AY14) -> 0 | BX14: =SUM(AB14,AZ14) -> 0 | BY14: =IF(BB14>0,SUM(BT14,BU14,BV14,BW14,BX14),"") | BZ14: =IF(E14="","",VLOOKUP(B14&$BZ$1,FLNTRANSPOSE!$F$3:$DP$102,105,0)) | CA14: =IF(E14="","",VLOOKUP(B14&$BZ$1,FLNTRANSPOSE!$F$3:$DP$102,107,0)) | CB14: =IF(E14="","",VLOOKUP(B14&$BZ$1,FLNTRANSPOSE!$F$3:$DP$102,109,0)) | CC14: =IF(E14="","",VLOOKUP(B14&$BZ$1,FLNTRANSPOSE!$F$3:$DP$102,111,0)) | CD14: =IF(E14="","",VLOOKUP(B14&$BZ$1,FLNTRANSPOSE!$F$3:$DP$102,113,0)) | CE14: =IF(E14="","",VLOOKUP(B14&$BZ$1,FLNTRANSPOSE!$F$3:$DP$102,115,0)) | CF14: =IF(E14="","",SUM(BZ14,CA14,CB14,CC14,CD14,CE14)) | CG14: =IF(E14="","",VLOOKUP(B14&$CG$1,FLNTRANSPOSE!$F$3:$DP$102,105,0)) | CH14: =IF(E14="","",VLOOKUP(B14&$CG$1,FLNTRANSPOSE!$F$3:$DP$102,107,0)) | CI14: =IF(E14="","",VLOOKUP(B14&$CG$1,FLNTRANSPOSE!$F$3:$DP$102,109,0)) | CJ14: =IF(E14="","",VLOOKUP(B14&$CG$1,FLNTRANSPOSE!$F$3:$DP$102,111,0)) | CK14: =IF(E14="","",VLOOKUP(B14&$CG$1,FLNTRANSPOSE!$F$3:$DP$102,113,0)) | CL14: =IF(E14="","",VLOOKUP(B14&$CG$1,FLNTRANSPOSE!$F$3:$DP$102,115,0)) | CM14: =IF(E14="","",SUM(CG14,CH14,CI14,CJ14,CK14,CL14)) | CN14: =IF(E14="","",VLOOKUP(B14&$CN$1,FLNTRANSPOSE!$F$3:$DP$102,105,0)) | CO14: =IF(E14="","",VLOOKUP(B14&$CN$1,FLNTRANSPOSE!$F$3:$DP$102,107,0)) | CP14: =IF(E14="","",VLOOKUP(B14&$CN$1,FLNTRANSPOSE!$F$3:$DP$102,109,0)) | CQ14: =IF(E14="","",VLOOKUP(B14&$CN$1,FLNTRANSPOSE!$F$3:$DP$102,111,0)) | CR14: =IF(E14="","",VLOOKUP(B14&$CN$1,FLNTRANSPOSE!$F$3:$DP$102,113,0)) | CS14: =IF(E14="","",VLOOKUP(B14&$CN$1,FLNTRANSPOSE!$F$3:$DP$102,115,0)) | CT14: =IF(E14="","",SUM(CN14,CO14,CP14,CQ14,CR14,CS14))
A15: 13 | E15: =IF(C15>0,MIN(C15-D15),"") | H15: =IF(F15>0,MIN(F15-G15),"") | I15: =B15&$J$1 -> HINDI | O15: =IF(F15>0,SUM(J15,K15,L15,M15,N15),"") | P15: =B15&$Q$1 -> MATHS | V15: =IF(F15>0,SUM(Q15,R15,S15,T15,U15),"") | W15: =B15&$X$1 -> ENGLISH | AC15: =IF(F15>0,SUM(X15,Y15,Z15,AA15,AB15),"") | AF15: =IF(AD15>0,MIN(AD15-AE15),"") | AG15: =B15&$AH$1 -> HINDI | AM15: =IF(AD15>0,SUM(AH15,AI15,AJ15,AK15,AL15),"") | AN15: =B15&$AO$1 -> MATHS | AT15: =IF(AD15>0,SUM(AO15,AP15,AQ15,AR15,AS15),"") | AU15: =B15&$AV$1 -> ENGLISH | BA15: =IF(AD15>0,SUM(AV15,AW15,AX15,AY15,AZ15),"") | BB15: =SUM(F15,AD15) -> 0 | BC15: =SUM(G15,AE15) -> 0 | BD15: =IF(BB15>0,MIN(BB15-BC15),"") | BE15: =B15&$BF$1 -> HINDI | BF15: =SUM(J15,AH15) -> 0 | BG15: =SUM(K15,AI15) -> 0 | BH15: =SUM(L15,AJ15) -> 0 | BI15: =SUM(M15,AK15) -> 0 | BJ15: =SUM(N15,AL15) -> 0 | BK15: =IF(BB15>0,SUM(BF15,BG15,BH15,BI15,BJ15),"") | BL15: =B15&$BM$1 -> MATHS | BM15: =SUM(Q15,AO15) -> 0 | BN15: =SUM(R15,AP15) -> 0 | BO15: =SUM(S15,AQ15) -> 0 | BP15: =SUM(T15,AR15) -> 0 | BQ15: =SUM(U15,AS15) -> 0 | BR15: =IF(BB15>0,SUM(BM15,BN15,BO15,BP15,BQ15),"") | BS15: =B15&$BT$1 -> ENGLISH | BT15: =SUM(X15,AV15) -> 0 | BU15: =SUM(Y15,AW15) -> 0 | BV15: =SUM(Z15,AX15) -> 0 | BW15: =SUM(AA15,AY15) -> 0 | BX15: =SUM(AB15,AZ15) -> 0 | BY15: =IF(BB15>0,SUM(BT15,BU15,BV15,BW15,BX15),"") | BZ15: =IF(E15="","",VLOOKUP(B15&$BZ$1,FLNTRANSPOSE!$F$3:$DP$102,105,0)) | CA15: =IF(E15="","",VLOOKUP(B15&$BZ$1,FLNTRANSPOSE!$F$3:$DP$102,107,0)) | CB15: =IF(E15="","",VLOOKUP(B15&$BZ$1,FLNTRANSPOSE!$F$3:$DP$102,109,0)) | CC15: =IF(E15="","",VLOOKUP(B15&$BZ$1,FLNTRANSPOSE!$F$3:$DP$102,111,0)) | CD15: =IF(E15="","",VLOOKUP(B15&$BZ$1,FLNTRANSPOSE!$F$3:$DP$102,113,0)) | CE15: =IF(E15="","",VLOOKUP(B15&$BZ$1,FLNTRANSPOSE!$F$3:$DP$102,115,0)) | CF15: =IF(E15="","",SUM(BZ15,CA15,CB15,CC15,CD15,CE15)) | CG15: =IF(E15="","",VLOOKUP(B15&$CG$1,FLNTRANSPOSE!$F$3:$DP$102,105,0)) | CH15: =IF(E15="","",VLOOKUP(B15&$CG$1,FLNTRANSPOSE!$F$3:$DP$102,107,0)) | CI15: =IF(E15="","",VLOOKUP(B15&$CG$1,FLNTRANSPOSE!$F$3:$DP$102,109,0)) | CJ15: =IF(E15="","",VLOOKUP(B15&$CG$1,FLNTRANSPOSE!$F$3:$DP$102,111,0)) | CK15: =IF(E15="","",VLOOKUP(B15&$CG$1,FLNTRANSPOSE!$F$3:$DP$102,113,0)) | CL15: =IF(E15="","",VLOOKUP(B15&$CG$1,FLNTRANSPOSE!$F$3:$DP$102,115,0)) | CM15: =IF(E15="","",SUM(CG15,CH15,CI15,CJ15,CK15,CL15)) | CN15: =IF(E15="","",VLOOKUP(B15&$CN$1,FLNTRANSPOSE!$F$3:$DP$102,105,0)) | CO15: =IF(E15="","",VLOOKUP(B15&$CN$1,FLNTRANSPOSE!$F$3:$DP$102,107,0)) | CP15: =IF(E15="","",VLOOKUP(B15&$CN$1,FLNTRANSPOSE!$F$3:$DP$102,109,0)) | CQ15: =IF(E15="","",VLOOKUP(B15&$CN$1,FLNTRANSPOSE!$F$3:$DP$102,111,0)) | CR15: =IF(E15="","",VLOOKUP(B15&$CN$1,FLNTRANSPOSE!$F$3:$DP$102,113,0)) | CS15: =IF(E15="","",VLOOKUP(B15&$CN$1,FLNTRANSPOSE!$F$3:$DP$102,115,0)) | CT15: =IF(E15="","",SUM(CN15,CO15,CP15,CQ15,CR15,CS15))
A16: 14 | E16: =IF(C16>0,MIN(C16-D16),"") | H16: =IF(F16>0,MIN(F16-G16),"") | I16: =B16&$J$1 -> HINDI | O16: =IF(F16>0,SUM(J16,K16,L16,M16,N16),"") | P16: =B16&$Q$1 -> MATHS | V16: =IF(F16>0,SUM(Q16,R16,S16,T16,U16),"") | W16: =B16&$X$1 -> ENGLISH | AC16: =IF(F16>0,SUM(X16,Y16,Z16,AA16,AB16),"") | AF16: =IF(AD16>0,MIN(AD16-AE16),"") | AG16: =B16&$AH$1 -> HINDI | AM16: =IF(AD16>0,SUM(AH16,AI16,AJ16,AK16,AL16),"") | AN16: =B16&$AO$1 -> MATHS | AT16: =IF(AD16>0,SUM(AO16,AP16,AQ16,AR16,AS16),"") | AU16: =B16&$AV$1 -> ENGLISH | BA16: =IF(AD16>0,SUM(AV16,AW16,AX16,AY16,AZ16),"") | BB16: =SUM(F16,AD16) -> 0 | BC16: =SUM(G16,AE16) -> 0 | BD16: =IF(BB16>0,MIN(BB16-BC16),"") | BE16: =B16&$BF$1 -> HINDI | BF16: =SUM(J16,AH16) -> 0 | BG16: =SUM(K16,AI16) -> 0 | BH16: =SUM(L16,AJ16) -> 0 | BI16: =SUM(M16,AK16) -> 0 | BJ16: =SUM(N16,AL16) -> 0 | BK16: =IF(BB16>0,SUM(BF16,BG16,BH16,BI16,BJ16),"") | BL16: =B16&$BM$1 -> MATHS | BM16: =SUM(Q16,AO16) -> 0 | BN16: =SUM(R16,AP16) -> 0 | BO16: =SUM(S16,AQ16) -> 0 | BP16: =SUM(T16,AR16) -> 0 | BQ16: =SUM(U16,AS16) -> 0 | BR16: =IF(BB16>0,SUM(BM16,BN16,BO16,BP16,BQ16),"") | BS16: =B16&$BT$1 -> ENGLISH | BT16: =SUM(X16,AV16) -> 0 | BU16: =SUM(Y16,AW16) -> 0 | BV16: =SUM(Z16,AX16) -> 0 | BW16: =SUM(AA16,AY16) -> 0 | BX16: =SUM(AB16,AZ16) -> 0 | BY16: =IF(BB16>0,SUM(BT16,BU16,BV16,BW16,BX16),"") | BZ16: =IF(E16="","",VLOOKUP(B16&$BZ$1,FLNTRANSPOSE!$F$3:$DP$102,105,0)) | CA16: =IF(E16="","",VLOOKUP(B16&$BZ$1,FLNTRANSPOSE!$F$3:$DP$102,107,0)) | CB16: =IF(E16="","",VLOOKUP(B16&$BZ$1,FLNTRANSPOSE!$F$3:$DP$102,109,0)) | CC16: =IF(E16="","",VLOOKUP(B16&$BZ$1,FLNTRANSPOSE!$F$3:$DP$102,111,0)) | CD16: =IF(E16="","",VLOOKUP(B16&$BZ$1,FLNTRANSPOSE!$F$3:$DP$102,113,0)) | CE16: =IF(E16="","",VLOOKUP(B16&$BZ$1,FLNTRANSPOSE!$F$3:$DP$102,115,0)) | CF16: =IF(E16="","",SUM(BZ16,CA16,CB16,CC16,CD16,CE16)) | CG16: =IF(E16="","",VLOOKUP(B16&$CG$1,FLNTRANSPOSE!$F$3:$DP$102,105,0)) | CH16: =IF(E16="","",VLOOKUP(B16&$CG$1,FLNTRANSPOSE!$F$3:$DP$102,107,0)) | CI16: =IF(E16="","",VLOOKUP(B16&$CG$1,FLNTRANSPOSE!$F$3:$DP$102,109,0)) | CJ16: =IF(E16="","",VLOOKUP(B16&$CG$1,FLNTRANSPOSE!$F$3:$DP$102,111,0)) | CK16: =IF(E16="","",VLOOKUP(B16&$CG$1,FLNTRANSPOSE!$F$3:$DP$102,113,0)) | CL16: =IF(E16="","",VLOOKUP(B16&$CG$1,FLNTRANSPOSE!$F$3:$DP$102,115,0)) | CM16: =IF(E16="","",SUM(CG16,CH16,CI16,CJ16,CK16,CL16)) | CN16: =IF(E16="","",VLOOKUP(B16&$CN$1,FLNTRANSPOSE!$F$3:$DP$102,105,0)) | CO16: =IF(E16="","",VLOOKUP(B16&$CN$1,FLNTRANSPOSE!$F$3:$DP$102,107,0)) | CP16: =IF(E16="","",VLOOKUP(B16&$CN$1,FLNTRANSPOSE!$F$3:$DP$102,109,0)) | CQ16: =IF(E16="","",VLOOKUP(B16&$CN$1,FLNTRANSPOSE!$F$3:$DP$102,111,0)) | CR16: =IF(E16="","",VLOOKUP(B16&$CN$1,FLNTRANSPOSE!$F$3:$DP$102,113,0)) | CS16: =IF(E16="","",VLOOKUP(B16&$CN$1,FLNTRANSPOSE!$F$3:$DP$102,115,0)) | CT16: =IF(E16="","",SUM(CN16,CO16,CP16,CQ16,CR16,CS16))
A17: 15 | E17: =IF(C17>0,MIN(C17-D17),"") | H17: =IF(F17>0,MIN(F17-G17),"") | I17: =B17&$J$1 -> HINDI | O17: =IF(F17>0,SUM(J17,K17,L17,M17,N17),"") | P17: =B17&$Q$1 -> MATHS | V17: =IF(F17>0,SUM(Q17,R17,S17,T17,U17),"") | W17: =B17&$X$1 -> ENGLISH | AC17: =IF(F17>0,SUM(X17,Y17,Z17,AA17,AB17),"") | AF17: =IF(AD17>0,MIN(AD17-AE17),"") | AG17: =B17&$AH$1 -> HINDI | AM17: =IF(AD17>0,SUM(AH17,AI17,AJ17,AK17,AL17),"") | AN17: =B17&$AO$1 -> MATHS | AT17: =IF(AD17>0,SUM(AO17,AP17,AQ17,AR17,AS17),"") | AU17: =B17&$AV$1 -> ENGLISH | BA17: =IF(AD17>0,SUM(AV17,AW17,AX17,AY17,AZ17),"") | BB17: =SUM(F17,AD17) -> 0 | BC17: =SUM(G17,AE17) -> 0 | BD17: =IF(BB17>0,MIN(BB17-BC17),"") | BE17: =B17&$BF$1 -> HINDI | BF17: =SUM(J17,AH17) -> 0 | BG17: =SUM(K17,AI17) -> 0 | BH17: =SUM(L17,AJ17) -> 0 | BI17: =SUM(M17,AK17) -> 0 | BJ17: =SUM(N17,AL17) -> 0 | BK17: =IF(BB17>0,SUM(BF17,BG17,BH17,BI17,BJ17),"") | BL17: =B17&$BM$1 -> MATHS | BM17: =SUM(Q17,AO17) -> 0 | BN17: =SUM(R17,AP17) -> 0 | BO17: =SUM(S17,AQ17) -> 0 | BP17: =SUM(T17,AR17) -> 0 | BQ17: =SUM(U17,AS17) -> 0 | BR17: =IF(BB17>0,SUM(BM17,BN17,BO17,BP17,BQ17),"") | BS17: =B17&$BT$1 -> ENGLISH | BT17: =SUM(X17,AV17) -> 0 | BU17: =SUM(Y17,AW17) -> 0 | BV17: =SUM(Z17,AX17) -> 0 | BW17: =SUM(AA17,AY17) -> 0 | BX17: =SUM(AB17,AZ17) -> 0 | BY17: =IF(BB17>0,SUM(BT17,BU17,BV17,BW17,BX17),"") | BZ17: =IF(E17="","",VLOOKUP(B17&$BZ$1,FLNTRANSPOSE!$F$3:$DP$102,105,0)) | CA17: =IF(E17="","",VLOOKUP(B17&$BZ$1,FLNTRANSPOSE!$F$3:$DP$102,107,0)) | CB17: =IF(E17="","",VLOOKUP(B17&$BZ$1,FLNTRANSPOSE!$F$3:$DP$102,109,0)) | CC17: =IF(E17="","",VLOOKUP(B17&$BZ$1,FLNTRANSPOSE!$F$3:$DP$102,111,0)) | CD17: =IF(E17="","",VLOOKUP(B17&$BZ$1,FLNTRANSPOSE!$F$3:$DP$102,113,0)) | CE17: =IF(E17="","",VLOOKUP(B17&$BZ$1,FLNTRANSPOSE!$F$3:$DP$102,115,0)) | CF17: =IF(E17="","",SUM(BZ17,CA17,CB17,CC17,CD17,CE17)) | CG17: =IF(E17="","",VLOOKUP(B17&$CG$1,FLNTRANSPOSE!$F$3:$DP$102,105,0)) | CH17: =IF(E17="","",VLOOKUP(B17&$CG$1,FLNTRANSPOSE!$F$3:$DP$102,107,0)) | CI17: =IF(E17="","",VLOOKUP(B17&$CG$1,FLNTRANSPOSE!$F$3:$DP$102,109,0)) | CJ17: =IF(E17="","",VLOOKUP(B17&$CG$1,FLNTRANSPOSE!$F$3:$DP$102,111,0)) | CK17: =IF(E17="","",VLOOKUP(B17&$CG$1,FLNTRANSPOSE!$F$3:$DP$102,113,0)) | CL17: =IF(E17="","",VLOOKUP(B17&$CG$1,FLNTRANSPOSE!$F$3:$DP$102,115,0)) | CM17: =IF(E17="","",SUM(CG17,CH17,CI17,CJ17,CK17,CL17)) | CN17: =IF(E17="","",VLOOKUP(B17&$CN$1,FLNTRANSPOSE!$F$3:$DP$102,105,0)) | CO17: =IF(E17="","",VLOOKUP(B17&$CN$1,FLNTRANSPOSE!$F$3:$DP$102,107,0)) | CP17: =IF(E17="","",VLOOKUP(B17&$CN$1,FLNTRANSPOSE!$F$3:$DP$102,109,0)) | CQ17: =IF(E17="","",VLOOKUP(B17&$CN$1,FLNTRANSPOSE!$F$3:$DP$102,111,0)) | CR17: =IF(E17="","",VLOOKUP(B17&$CN$1,FLNTRANSPOSE!$F$3:$DP$102,113,0)) | CS17: =IF(E17="","",VLOOKUP(B17&$CN$1,FLNTRANSPOSE!$F$3:$DP$102,115,0)) | CT17: =IF(E17="","",SUM(CN17,CO17,CP17,CQ17,CR17,CS17))
A18: 16 | E18: =IF(C18>0,MIN(C18-D18),"") | H18: =IF(F18>0,MIN(F18-G18),"") | I18: =B18&$J$1 -> HINDI | O18: =IF(F18>0,SUM(J18,K18,L18,M18,N18),"") | P18: =B18&$Q$1 -> MATHS | V18: =IF(F18>0,SUM(Q18,R18,S18,T18,U18),"") | W18: =B18&$X$1 -> ENGLISH | AC18: =IF(F18>0,SUM(X18,Y18,Z18,AA18,AB18),"") | AF18: =IF(AD18>0,MIN(AD18-AE18),"") | AG18: =B18&$AH$1 -> HINDI | AM18: =IF(AD18>0,SUM(AH18,AI18,AJ18,AK18,AL18),"") | AN18: =B18&$AO$1 -> MATHS | AT18: =IF(AD18>0,SUM(AO18,AP18,AQ18,AR18,AS18),"") | AU18: =B18&$AV$1 -> ENGLISH | BA18: =IF(AD18>0,SUM(AV18,AW18,AX18,AY18,AZ18),"") | BB18: =SUM(F18,AD18) -> 0 | BC18: =SUM(G18,AE18) -> 0 | BD18: =IF(BB18>0,MIN(BB18-BC18),"") | BE18: =B18&$BF$1 -> HINDI | BF18: =SUM(J18,AH18) -> 0 | BG18: =SUM(K18,AI18) -> 0 | BH18: =SUM(L18,AJ18) -> 0 | BI18: =SUM(M18,AK18) -> 0 | BJ18: =SUM(N18,AL18) -> 0 | BK18: =IF(BB18>0,SUM(BF18,BG18,BH18,BI18,BJ18),"") | BL18: =B18&$BM$1 -> MATHS | BM18: =SUM(Q18,AO18) -> 0 | BN18: =SUM(R18,AP18) -> 0 | BO18: =SUM(S18,AQ18) -> 0 | BP18: =SUM(T18,AR18) -> 0 | BQ18: =SUM(U18,AS18) -> 0 | BR18: =IF(BB18>0,SUM(BM18,BN18,BO18,BP18,BQ18),"") | BS18: =B18&$BT$1 -> ENGLISH | BT18: =SUM(X18,AV18) -> 0 | BU18: =SUM(Y18,AW18) -> 0 | BV18: =SUM(Z18,AX18) -> 0 | BW18: =SUM(AA18,AY18) -> 0 | BX18: =SUM(AB18,AZ18) -> 0 | BY18: =IF(BB18>0,SUM(BT18,BU18,BV18,BW18,BX18),"") | BZ18: =IF(E18="","",VLOOKUP(B18&$BZ$1,FLNTRANSPOSE!$F$3:$DP$102,105,0)) | CA18: =IF(E18="","",VLOOKUP(B18&$BZ$1,FLNTRANSPOSE!$F$3:$DP$102,107,0)) | CB18: =IF(E18="","",VLOOKUP(B18&$BZ$1,FLNTRANSPOSE!$F$3:$DP$102,109,0)) | CC18: =IF(E18="","",VLOOKUP(B18&$BZ$1,FLNTRANSPOSE!$F$3:$DP$102,111,0)) | CD18: =IF(E18="","",VLOOKUP(B18&$BZ$1,FLNTRANSPOSE!$F$3:$DP$102,113,0)) | CE18: =IF(E18="","",VLOOKUP(B18&$BZ$1,FLNTRANSPOSE!$F$3:$DP$102,115,0)) | CF18: =IF(E18="","",SUM(BZ18,CA18,CB18,CC18,CD18,CE18)) | CG18: =IF(E18="","",VLOOKUP(B18&$CG$1,FLNTRANSPOSE!$F$3:$DP$102,105,0)) | CH18: =IF(E18="","",VLOOKUP(B18&$CG$1,FLNTRANSPOSE!$F$3:$DP$102,107,0)) | CI18: =IF(E18="","",VLOOKUP(B18&$CG$1,FLNTRANSPOSE!$F$3:$DP$102,109,0)) | CJ18: =IF(E18="","",VLOOKUP(B18&$CG$1,FLNTRANSPOSE!$F$3:$DP$102,111,0)) | CK18: =IF(E18="","",VLOOKUP(B18&$CG$1,FLNTRANSPOSE!$F$3:$DP$102,113,0)) | CL18: =IF(E18="","",VLOOKUP(B18&$CG$1,FLNTRANSPOSE!$F$3:$DP$102,115,0)) | CM18: =IF(E18="","",SUM(CG18,CH18,CI18,CJ18,CK18,CL18)) | CN18: =IF(E18="","",VLOOKUP(B18&$CN$1,FLNTRANSPOSE!$F$3:$DP$102,105,0)) | CO18: =IF(E18="","",VLOOKUP(B18&$CN$1,FLNTRANSPOSE!$F$3:$DP$102,107,0)) | CP18: =IF(E18="","",VLOOKUP(B18&$CN$1,FLNTRANSPOSE!$F$3:$DP$102,109,0)) | CQ18: =IF(E18="","",VLOOKUP(B18&$CN$1,FLNTRANSPOSE!$F$3:$DP$102,111,0)) | CR18: =IF(E18="","",VLOOKUP(B18&$CN$1,FLNTRANSPOSE!$F$3:$DP$102,113,0)) | CS18: =IF(E18="","",VLOOKUP(B18&$CN$1,FLNTRANSPOSE!$F$3:$DP$102,115,0)) | CT18: =IF(E18="","",SUM(CN18,CO18,CP18,CQ18,CR18,CS18))
A19: 17 | E19: =IF(C19>0,MIN(C19-D19),"") | H19: =IF(F19>0,MIN(F19-G19),"") | I19: =B19&$J$1 -> HINDI | O19: =IF(F19>0,SUM(J19,K19,L19,M19,N19),"") | P19: =B19&$Q$1 -> MATHS | V19: =IF(F19>0,SUM(Q19,R19,S19,T19,U19),"") | W19: =B19&$X$1 -> ENGLISH | AC19: =IF(F19>0,SUM(X19,Y19,Z19,AA19,AB19),"") | AF19: =IF(AD19>0,MIN(AD19-AE19),"") | AG19: =B19&$AH$1 -> HINDI | AM19: =IF(AD19>0,SUM(AH19,AI19,AJ19,AK19,AL19),"") | AN19: =B19&$AO$1 -> MATHS | AT19: =IF(AD19>0,SUM(AO19,AP19,AQ19,AR19,AS19),"") | AU19: =B19&$AV$1 -> ENGLISH | BA19: =IF(AD19>0,SUM(AV19,AW19,AX19,AY19,AZ19),"") | BB19: =SUM(F19,AD19) -> 0 | BC19: =SUM(G19,AE19) -> 0 | BD19: =IF(BB19>0,MIN(BB19-BC19),"") | BE19: =B19&$BF$1 -> HINDI | BF19: =SUM(J19,AH19) -> 0 | BG19: =SUM(K19,AI19) -> 0 | BH19: =SUM(L19,AJ19) -> 0 | BI19: =SUM(M19,AK19) -> 0 | BJ19: =SUM(N19,AL19) -> 0 | BK19: =IF(BB19>0,SUM(BF19,BG19,BH19,BI19,BJ19),"") | BL19: =B19&$BM$1 -> MATHS | BM19: =SUM(Q19,AO19) -> 0 | BN19: =SUM(R19,AP19) -> 0 | BO19: =SUM(S19,AQ19) -> 0 | BP19: =SUM(T19,AR19) -> 0 | BQ19: =SUM(U19,AS19) -> 0 | BR19: =IF(BB19>0,SUM(BM19,BN19,BO19,BP19,BQ19),"") | BS19: =B19&$BT$1 -> ENGLISH | BT19: =SUM(X19,AV19) -> 0 | BU19: =SUM(Y19,AW19) -> 0 | BV19: =SUM(Z19,AX19) -> 0 | BW19: =SUM(AA19,AY19) -> 0 | BX19: =SUM(AB19,AZ19) -> 0 | BY19: =IF(BB19>0,SUM(BT19,BU19,BV19,BW19,BX19),"") | BZ19: =IF(E19="","",VLOOKUP(B19&$BZ$1,FLNTRANSPOSE!$F$3:$DP$102,105,0)) | CA19: =IF(E19="","",VLOOKUP(B19&$BZ$1,FLNTRANSPOSE!$F$3:$DP$102,107,0)) | CB19: =IF(E19="","",VLOOKUP(B19&$BZ$1,FLNTRANSPOSE!$F$3:$DP$102,109,0)) | CC19: =IF(E19="","",VLOOKUP(B19&$BZ$1,FLNTRANSPOSE!$F$3:$DP$102,111,0)) | CD19: =IF(E19="","",VLOOKUP(B19&$BZ$1,FLNTRANSPOSE!$F$3:$DP$102,113,0)) | CE19: =IF(E19="","",VLOOKUP(B19&$BZ$1,FLNTRANSPOSE!$F$3:$DP$102,115,0)) | CF19: =IF(E19="","",SUM(BZ19,CA19,CB19,CC19,CD19,CE19)) | CG19: =IF(E19="","",VLOOKUP(B19&$CG$1,FLNTRANSPOSE!$F$3:$DP$102,105,0)) | CH19: =IF(E19="","",VLOOKUP(B19&$CG$1,FLNTRANSPOSE!$F$3:$DP$102,107,0)) | CI19: =IF(E19="","",VLOOKUP(B19&$CG$1,FLNTRANSPOSE!$F$3:$DP$102,109,0)) | CJ19: =IF(E19="","",VLOOKUP(B19&$CG$1,FLNTRANSPOSE!$F$3:$DP$102,111,0)) | CK19: =IF(E19="","",VLOOKUP(B19&$CG$1,FLNTRANSPOSE!$F$3:$DP$102,113,0)) | CL19: =IF(E19="","",VLOOKUP(B19&$CG$1,FLNTRANSPOSE!$F$3:$DP$102,115,0)) | CM19: =IF(E19="","",SUM(CG19,CH19,CI19,CJ19,CK19,CL19)) | CN19: =IF(E19="","",VLOOKUP(B19&$CN$1,FLNTRANSPOSE!$F$3:$DP$102,105,0)) | CO19: =IF(E19="","",VLOOKUP(B19&$CN$1,FLNTRANSPOSE!$F$3:$DP$102,107,0)) | CP19: =IF(E19="","",VLOOKUP(B19&$CN$1,FLNTRANSPOSE!$F$3:$DP$102,109,0)) | CQ19: =IF(E19="","",VLOOKUP(B19&$CN$1,FLNTRANSPOSE!$F$3:$DP$102,111,0)) | CR19: =IF(E19="","",VLOOKUP(B19&$CN$1,FLNTRANSPOSE!$F$3:$DP$102,113,0)) | CS19: =IF(E19="","",VLOOKUP(B19&$CN$1,FLNTRANSPOSE!$F$3:$DP$102,115,0)) | CT19: =IF(E19="","",SUM(CN19,CO19,CP19,CQ19,CR19,CS19))
A20: 18 | E20: =IF(C20>0,MIN(C20-D20),"") | H20: =IF(F20>0,MIN(F20-G20),"") | I20: =B20&$J$1 -> HINDI | O20: =IF(F20>0,SUM(J20,K20,L20,M20,N20),"") | P20: =B20&$Q$1 -> MATHS | V20: =IF(F20>0,SUM(Q20,R20,S20,T20,U20),"") | W20: =B20&$X$1 -> ENGLISH | AC20: =IF(F20>0,SUM(X20,Y20,Z20,AA20,AB20),"") | AF20: =IF(AD20>0,MIN(AD20-AE20),"") | AG20: =B20&$AH$1 -> HINDI | AM20: =IF(AD20>0,SUM(AH20,AI20,AJ20,AK20,AL20),"") | AN20: =B20&$AO$1 -> MATHS | AT20: =IF(AD20>0,SUM(AO20,AP20,AQ20,AR20,AS20),"") | AU20: =B20&$AV$1 -> ENGLISH | BA20: =IF(AD20>0,SUM(AV20,AW20,AX20,AY20,AZ20),"") | BB20: =SUM(F20,AD20) -> 0 | BC20: =SUM(G20,AE20) -> 0 | BD20: =IF(BB20>0,MIN(BB20-BC20),"") | BE20: =B20&$BF$1 -> HINDI | BF20: =SUM(J20,AH20) -> 0 | BG20: =SUM(K20,AI20) -> 0 | BH20: =SUM(L20,AJ20) -> 0 | BI20: =SUM(M20,AK20) -> 0 | BJ20: =SUM(N20,AL20) -> 0 | BK20: =IF(BB20>0,SUM(BF20,BG20,BH20,BI20,BJ20),"") | BL20: =B20&$BM$1 -> MATHS | BM20: =SUM(Q20,AO20) -> 0 | BN20: =SUM(R20,AP20) -> 0 | BO20: =SUM(S20,AQ20) -> 0 | BP20: =SUM(T20,AR20) -> 0 | BQ20: =SUM(U20,AS20) -> 0 | BR20: =IF(BB20>0,SUM(BM20,BN20,BO20,BP20,BQ20),"") | BS20: =B20&$BT$1 -> ENGLISH | BT20: =SUM(X20,AV20) -> 0 | BU20: =SUM(Y20,AW20) -> 0 | BV20: =SUM(Z20,AX20) -> 0 | BW20: =SUM(AA20,AY20) -> 0 | BX20: =SUM(AB20,AZ20) -> 0 | BY20: =IF(BB20>0,SUM(BT20,BU20,BV20,BW20,BX20),"") | BZ20: =IF(E20="","",VLOOKUP(B20&$BZ$1,FLNTRANSPOSE!$F$3:$DP$102,105,0)) | CA20: =IF(E20="","",VLOOKUP(B20&$BZ$1,FLNTRANSPOSE!$F$3:$DP$102,107,0)) | CB20: =IF(E20="","",VLOOKUP(B20&$BZ$1,FLNTRANSPOSE!$F$3:$DP$102,109,0)) | CC20: =IF(E20="","",VLOOKUP(B20&$BZ$1,FLNTRANSPOSE!$F$3:$DP$102,111,0)) | CD20: =IF(E20="","",VLOOKUP(B20&$BZ$1,FLNTRANSPOSE!$F$3:$DP$102,113,0)) | CE20: =IF(E20="","",VLOOKUP(B20&$BZ$1,FLNTRANSPOSE!$F$3:$DP$102,115,0)) | CF20: =IF(E20="","",SUM(BZ20,CA20,CB20,CC20,CD20,CE20)) | CG20: =IF(E20="","",VLOOKUP(B20&$CG$1,FLNTRANSPOSE!$F$3:$DP$102,105,0)) | CH20: =IF(E20="","",VLOOKUP(B20&$CG$1,FLNTRANSPOSE!$F$3:$DP$102,107,0)) | CI20: =IF(E20="","",VLOOKUP(B20&$CG$1,FLNTRANSPOSE!$F$3:$DP$102,109,0)) | CJ20: =IF(E20="","",VLOOKUP(B20&$CG$1,FLNTRANSPOSE!$F$3:$DP$102,111,0)) | CK20: =IF(E20="","",VLOOKUP(B20&$CG$1,FLNTRANSPOSE!$F$3:$DP$102,113,0)) | CL20: =IF(E20="","",VLOOKUP(B20&$CG$1,FLNTRANSPOSE!$F$3:$DP$102,115,0)) | CM20: =IF(E20="","",SUM(CG20,CH20,CI20,CJ20,CK20,CL20)) | CN20: =IF(E20="","",VLOOKUP(B20&$CN$1,FLNTRANSPOSE!$F$3:$DP$102,105,0)) | CO20: =IF(E20="","",VLOOKUP(B20&$CN$1,FLNTRANSPOSE!$F$3:$DP$102,107,0)) | CP20: =IF(E20="","",VLOOKUP(B20&$CN$1,FLNTRANSPOSE!$F$3:$DP$102,109,0)) | CQ20: =IF(E20="","",VLOOKUP(B20&$CN$1,FLNTRANSPOSE!$F$3:$DP$102,111,0)) | CR20: =IF(E20="","",VLOOKUP(B20&$CN$1,FLNTRANSPOSE!$F$3:$DP$102,113,0)) | CS20: =IF(E20="","",VLOOKUP(B20&$CN$1,FLNTRANSPOSE!$F$3:$DP$102,115,0)) | CT20: =IF(E20="","",SUM(CN20,CO20,CP20,CQ20,CR20,CS20))
